Workbook
Name _xlcn.WorksheetConnection_ContasareceberGeral2026CAMPINAS.xlsxTabela11: Tabela1
Name _xlcn.WorksheetConnection_JAN26A2G771: 'JAN-26'!$A$2:$G$77
Name SegmentaçãodeDados_CLIENTE1: #REF!
Name SegmentaçãodeDados_DIAS1: #REF!
Name SegmentaçãodeDados_EMISSÃO: #REF!
Name SegmentaçãodeDados_FATURAMENTO: #REF!
Name SegmentaçãodeDados_MÊS_FAT: #REF!
Name SegmentaçãodeDados_MÊS_PREV.: #REF!
Name SegmentaçãodeDados_MÊS_RECEB: #REF!
Name SegmentaçãodeDados_NFE1: #REF!
Name SegmentaçãodeDados_Recebido_em: #REF!
Name SegmentaçãodeDados_STATUS1: #REF!
Name SegmentaçãodeDados_V._Recebido: #REF!
Name SegmentaçãodeDados_VALOR1: #REF!
Name SegmentaçãodeDados_Vencimento: #REF!
Name SegmentaçãodeDados_VENCIMENTO2: #REF!

Sheet JAN-26
A2: EMISSÃO | B2: Vencimento | C2: Recebido em | D2: NF | E2: CLIENTE | F2: Valor a Receber | G2: Valor Recebido | I2: Tipo de Pgto | J2: Observação
G53: =IF(OR(C53 = "",C53="PENDENTE"), 0, IF(OR(C53<=B53,H53=1),F53,(F53*0.1966/100)*(C53-B53)+F53)) -> 0
G54: =IF(OR(C54 = "",C54="PENDENTE"), 0, IF(OR(C54<=B54,H54=1),F54,(F54*0.1966/100)*(C54-B54)+F54)) -> 0
G55: =IF(OR(C55 = "",C55="PENDENTE"), 0, IF(OR(C55<=B55,H55=1),F55,(F55*0.1966/100)*(C55-B55)+F55)) -> 0
G56: =IF(OR(C56 = "",C56="PENDENTE"), 0, IF(OR(C56<=B56,H56=1),F56,(F56*0.1966/100)*(C56-B56)+F56)) -> 0
G57: =IF(OR(C57 = "",C57="PENDENTE"), 0, IF(OR(C57<=B57,H57=1),F57,(F57*0.1966/100)*(C57-B57)+F57)) -> 0
G58: =IF(OR(C58 = "",C58="PENDENTE"), 0, IF(OR(C58<=B58,H58=1),F58,(F58*0.1966/100)*(C58-B58)+F58)) -> 0
G59: =IF(OR(C59 = "",C59="PENDENTE"), 0, IF(OR(C59<=B59,H59=1),F59,(F59*0.1966/100)*(C59-B59)+F59)) -> 0
G60: =IF(OR(C60 = "",C60="PENDENTE"), 0, IF(OR(C60<=B60,H60=1),F60,(F60*0.1966/100)*(C60-B60)+F60)) -> 0
G61: =IF(OR(C61 = "",C61="PENDENTE"), 0, IF(OR(C61<=B61,H61=1),F61,(F61*0.1966/100)*(C61-B61)+F61)) -> 0
G62: =IF(OR(C62 = "",C62="PENDENTE"), 0, IF(OR(C62<=B62,H62=1),F62,(F62*0.1966/100)*(C62-B62)+F62)) -> 0
G63: =IF(OR(C63 = "",C63="PENDENTE"), 0, IF(OR(C63<=B63,H63=1),F63,(F63*0.1966/100)*(C63-B63)+F63)) -> 0
G64: =IF(OR(C64 = "",C64="PENDENTE"), 0, IF(OR(C64<=B64,H64=1),F64,(F64*0.1966/100)*(C64-B64)+F64)) -> 0
... G76: =IF(OR(C76 = "",C76="PENDENTE"), 0, IF(OR(C76<=B76,H76=1),F76,(F76*0.1966/100)*(C76-B76)+F76)) -> 0
F77: =SUM(F3:F76) -> 0 | G77: =SUM(G3:G76) -> 0

Sheet FEV-26
A2: EMISSÃO | B2: Vencimento | C2: Recebido em | D2: NF | E2: CLIENTE | F2: Valor a Receber | G2: Valor Recebido | I2: Tipo de Pgto | J2: Observação
A53: 46079 | B53: 46080 | C53: 46077 | D53: 23685 | E53: I&M PAPEIS E EMBALAGENS LTDA | F53: 3981.74 | G53: =IF(OR(C53 = "",C53="PENDENTE"), 0, IF(OR(C53<=B53,H53=1),F53,(F53*0.1966/100)*(C53-B53)+F53)) -> 3981.74 | I53: DEP C/C
A54: 46079 | B54: 46107 | C54: 46106 | D54: 23686 | E54: UNIFRAX BRASIL LTDA | F54: 6208 | G54: =IF(OR(C54 = "",C54="PENDENTE"), 0, IF(OR(C54<=B54,H54=1),F54,(F54*0.1966/100)*(C54-B54)+F54)) -> 6208 | I54: BOLETO
A55: 46079 | B55: 46107 | C55: 46104 | D55: 23687 | E55: METALBAST EQUIPAMENTOS E MAQUINAS LTDA | F55: 1288 | G55: =IF(OR(C55 = "",C55="PENDENTE"), 0, IF(OR(C55<=B55,H55=1),F55,(F55*0.1966/100)*(C55-B55)+F55)) -> 1288 | I55: BOLETO
G56: =IF(OR(C56 = "",C56="PENDENTE"), 0, IF(OR(C56<=B56,H56=1),F56,(F56*0.1966/100)*(C56-B56)+F56)) -> 0
G57: =IF(OR(C57 = "",C57="PENDENTE"), 0, IF(OR(C57<=B57,H57=1),F57,(F57*0.1966/100)*(C57-B57)+F57)) -> 0
G58: =IF(OR(C58 = "",C58="PENDENTE"), 0, IF(OR(C58<=B58,H58=1),F58,(F58*0.1966/100)*(C58-B58)+F58)) -> 0
G59: =IF(OR(C59 = "",C59="PENDENTE"), 0, IF(OR(C59<=B59,H59=1),F59,(F59*0.1966/100)*(C59-B59)+F59)) -> 0
G60: =IF(OR(C60 = "",C60="PENDENTE"), 0, IF(OR(C60<=B60,H60=1),F60,(F60*0.1966/100)*(C60-B60)+F60)) -> 0
G61: =IF(OR(C61 = "",C61="PENDENTE"), 0, IF(OR(C61<=B61,H61=1),F61,(F61*0.1966/100)*(C61-B61)+F61)) -> 0
G62: =IF(OR(C62 = "",C62="PENDENTE"), 0, IF(OR(C62<=B62,H62=1),F62,(F62*0.1966/100)*(C62-B62)+F62)) -> 0
G63: =IF(OR(C63 = "",C63="PENDENTE"), 0, IF(OR(C63<=B63,H63=1),F63,(F63*0.1966/100)*(C63-B63)+F63)) -> 0
G64: =IF(OR(C64 = "",C64="PENDENTE"), 0, IF(OR(C64<=B64,H64=1),F64,(F64*0.1966/100)*(C64-B64)+F64)) -> 0
G65: =IF(OR(C65 = "",C65="PENDENTE"), 0, IF(OR(C65<=B65,H65=1),F65,(F65*0.1966/100)*(C65-B65)+F65)) -> 0
G66: =IF(OR(C66 = "",C66="PENDENTE"), 0, IF(OR(C66<=B66,H66=1),F66,(F66*0.1966/100)*(C66-B66)+F66)) -> 0
G67: =IF(OR(C67 = "",C67="PENDENTE"), 0, IF(OR(C67<=B67,H67=1),F67,(F67*0.1966/100)*(C67-B67)+F67)) -> 0
... G76: =IF(OR(C76 = "",C76="PENDENTE"), 0, IF(OR(C76<=B76,H76=1),F76,(F76*0.1966/100)*(C76-B76)+F76)) -> 0
F77: =SUM(F3:F76) -> 11477.74 | G77: =SUM(G3:G76) -> 11477.74

Sheet MAR-26
A2: EMISSÃO | B2: Vencimento | C2: Recebido em | D2: NF | E2: CLIENTE | F2: Valor a Receber | G2: Valor Recebido | I2: Tipo de Pgto | J2: Observação
A53: 46105 | B53: 46161 | C53: PENDENTE | D53: 23732 2 / 2 | E53: MERCANTIL UNIAO COM. DE MAT. P/ MAN. INDUSTRIAL LTDA | F53: 4087.5 | G53: =IF(OR(C53 = "",C53="PENDENTE"), 0, IF(OR(C53<=B53,H53=1),F53,(F53*0.1966/100)*(C53-B53)+F53)) -> 0 | I53: BOLETO
A54: 46106 | B54: 46134 | C54: 46134 | D54: 23733 | E54: ROCA SANITARIOS BRASIL LTDA | F54: 3149 | G54: =IF(OR(C54 = "",C54="PENDENTE"), 0, IF(OR(C54<=B54,H54=1),F54,(F54*0.1966/100)*(C54-B54)+F54)) -> 3149 | I54: DEP C/C
A55: 46106 | B55: 46134 | C55: 46134 | D55: 23734 | E55: NORTEL SUPRIMENTOS INDUSTRIAIS S/A | F55: 1258 | G55: =IF(OR(C55 = "",C55="PENDENTE"), 0, IF(OR(C55<=B55,H55=1),F55,(F55*0.1966/100)*(C55-B55)+F55)) -> 1258 | I55: DEP C/C
A56: 46107 | B56: 46142 | C56: PENDENTE | D56: 23735 | E56: RICLAN S/A | F56: 1476.11 | G56: =IF(OR(C56 = "",C56="PENDENTE"), 0, IF(OR(C56<=B56,H56=1),F56,(F56*0.1966/100)*(C56-B56)+F56)) -> 0 | I56: BOLETO
A57: 46107 | B57: 46149 | C57: PENDENTE | D57: 23736 | E57: MEXICHEM BRASIL IND. DE TRANSF. PLAST. LTDA | F57: 3076 | G57: =IF(OR(C57 = "",C57="PENDENTE"), 0, IF(OR(C57<=B57,H57=1),F57,(F57*0.1966/100)*(C57-B57)+F57)) -> 0 | I57: BOLETO
A58: 46107 | B58: 46142 | C58: PENDENTE | D58: 23737 | E58: RICLAN S/A | F58: 1118 | G58: =IF(OR(C58 = "",C58="PENDENTE"), 0, IF(OR(C58<=B58,H58=1),F58,(F58*0.1966/100)*(C58-B58)+F58)) -> 0 | I58: BOLETO
A59: 46107 | B59: 46167 | C59: PENDENTE | D59: 23738 | E59: MAHLE METAL LEVA S/A | F59: 942 | G59: =IF(OR(C59 = "",C59="PENDENTE"), 0, IF(OR(C59<=B59,H59=1),F59,(F59*0.1966/100)*(C59-B59)+F59)) -> 0 | I59: DEP C/C
A60: 46107 | B60: 46167 | C60: PENDENTE | D60: 23739 | E60: COOPER STANDARD AUTOMOTIVE BRASIL SEALING LTDA | F60: 1832.2 | G60: =IF(OR(C60 = "",C60="PENDENTE"), 0, IF(OR(C60<=B60,H60=1),F60,(F60*0.1966/100)*(C60-B60)+F60)) -> 0 | I60: DEP C/C
A61: 46111 | B61: 46139 | C61: PENDENTE | D61: 23740 | E61: ENERMAX ENGENHARIA COMERCIO E SERVICOS LTDA | F61: 2754 | G61: =IF(OR(C61 = "",C61="PENDENTE"), 0, IF(OR(C61<=B61,H61=1),F61,(F61*0.1966/100)*(C61-B61)+F61)) -> 0 | I61: BOLETO
A62: 46111 | B62: 46139 | C62: 46134 | D62: 23741 | E62: NOVA ADITIVOS BRASIL LTDA | F62: 4642 | G62: =IF(OR(C62 = "",C62="PENDENTE"), 0, IF(OR(C62<=B62,H62=1),F62,(F62*0.1966/100)*(C62-B62)+F62)) -> 4642 | I62: DEP C/C
A63: 46111 | B63: 46139 | C63: PENDENTE | D63: 23742 | E63: MERCANTIL UNIAO COM. DE MAT. P/ MAN. INDUSTRIAL LTDA | F63: 1333 | G63: =IF(OR(C63 = "",C63="PENDENTE"), 0, IF(OR(C63<=B63,H63=1),F63,(F63*0.1966/100)*(C63-B63)+F63)) -> 0 | I63: BOLETO
G64: =IF(OR(C64 = "",C64="PENDENTE"), 0, IF(OR(C64<=B64,H64=1),F64,(F64*0.1966/100)*(C64-B64)+F64)) -> 0
G65: =IF(OR(C65 = "",C65="PENDENTE"), 0, IF(OR(C65<=B65,H65=1),F65,(F65*0.1966/100)*(C65-B65)+F65)) -> 0
G66: =IF(OR(C66 = "",C66="PENDENTE"), 0, IF(OR(C66<=B66,H66=1),F66,(F66*0.1966/100)*(C66-B66)+F66)) -> 0
G67: =IF(OR(C67 = "",C67="PENDENTE"), 0, IF(OR(C67<=B67,H67=1),F67,(F67*0.1966/100)*(C67-B67)+F67)) -> 0
G68: =IF(OR(C68 = "",C68="PENDENTE"), 0, IF(OR(C68<=B68,H68=1),F68,(F68*0.1966/100)*(C68-B68)+F68)) -> 0
G69: =IF(OR(C69 = "",C69="PENDENTE"), 0, IF(OR(C69<=B69,H69=1),F69,(F69*0.1966/100)*(C69-B69)+F69)) -> 0
G70: =IF(OR(C70 = "",C70="PENDENTE"), 0, IF(OR(C70<=B70,H70=1),F70,(F70*0.1966/100)*(C70-B70)+F70)) -> 0
G71: =IF(OR(C71 = "",C71="PENDENTE"), 0, IF(OR(C71<=B71,H71=1),F71,(F71*0.1966/100)*(C71-B71)+F71)) -> 0
G72: =IF(OR(C72 = "",C72="PENDENTE"), 0, IF(OR(C72<=B72,H72=1),F72,(F72*0.1966/100)*(C72-B72)+F72)) -> 0
G73: =IF(OR(C73 = "",C73="PENDENTE"), 0, IF(OR(C73<=B73,H73=1),F73,(F73*0.1966/100)*(C73-B73)+F73)) -> 0
G74: =IF(OR(C74 = "",C74="PENDENTE"), 0, IF(OR(C74<=B74,H74=1),F74,(F74*0.1966/100)*(C74-B74)+F74)) -> 0
G75: =IF(OR(C75 = "",C75="PENDENTE"), 0, IF(OR(C75<=B75,H75=1),F75,(F75*0.1966/100)*(C75-B75)+F75)) -> 0
G76: =IF(OR(C76 = "",C76="PENDENTE"), 0, IF(OR(C76<=B76,H76=1),F76,(F76*0.1966/100)*(C76-B76)+F76)) -> 0
F77: =SUM(F3:F76) -> 25667.81 | G77: =SUM(G3:G76) -> 9049

Sheet ABR-26
A2: EMISSÃO | B2: Vencimento | C2: Recebido em | D2: NF | E2: CLIENTE | F2: Valor a Receber | G2: Valor Recebido | I2: Tipo de Pgto | J2: Observação
G53: =IF(OR(C53 = "",C53="PENDENTE"), 0, IF(OR(C53<=B53,H53=1),F53,(F53*0.1966/100)*(C53-B53)+F53)) -> 0
G54: =IF(OR(C54 = "",C54="PENDENTE"), 0, IF(OR(C54<=B54,H54=1),F54,(F54*0.1966/100)*(C54-B54)+F54)) -> 0
G55: =IF(OR(C55 = "",C55="PENDENTE"), 0, IF(OR(C55<=B55,H55=1),F55,(F55*0.1966/100)*(C55-B55)+F55)) -> 0
G56: =IF(OR(C56 = "",C56="PENDENTE"), 0, IF(OR(C56<=B56,H56=1),F56,(F56*0.1966/100)*(C56-B56)+F56)) -> 0
G57: =IF(OR(C57 = "",C57="PENDENTE"), 0, IF(OR(C57<=B57,H57=1),F57,(F57*0.1966/100)*(C57-B57)+F57)) -> 0
G58: =IF(OR(C58 = "",C58="PENDENTE"), 0, IF(OR(C58<=B58,H58=1),F58,(F58*0.1966/100)*(C58-B58)+F58)) -> 0
G59: =IF(OR(C59 = "",C59="PENDENTE"), 0, IF(OR(C59<=B59,H59=1),F59,(F59*0.1966/100)*(C59-B59)+F59)) -> 0
G60: =IF(OR(C60 = "",C60="PENDENTE"), 0, IF(OR(C60<=B60,H60=1),F60,(F60*0.1966/100)*(C60-B60)+F60)) -> 0
G61: =IF(OR(C61 = "",C61="PENDENTE"), 0, IF(OR(C61<=B61,H61=1),F61,(F61*0.1966/100)*(C61-B61)+F61)) -> 0
G62: =IF(OR(C62 = "",C62="PENDENTE"), 0, IF(OR(C62<=B62,H62=1),F62,(F62*0.1966/100)*(C62-B62)+F62)) -> 0
G63: =IF(OR(C63 = "",C63="PENDENTE"), 0, IF(OR(C63<=B63,H63=1),F63,(F63*0.1966/100)*(C63-B63)+F63)) -> 0
G64: =IF(OR(C64 = "",C64="PENDENTE"), 0, IF(OR(C64<=B64,H64=1),F64,(F64*0.1966/100)*(C64-B64)+F64)) -> 0
... G76: =IF(OR(C76 = "",C76="PENDENTE"), 0, IF(OR(C76<=B76,H76=1),F76,(F76*0.1966/100)*(C76-B76)+F76)) -> 0
F77: =SUM(F3:F76) -> 0 | G77: =SUM(G3:G76) -> 0

Sheet MAI-26
A2: EMISSÃO | B2: Vencimento | C2: Recebido em | D2: NF | E2: CLIENTE | F2: Valor a Receber | G2: Valor Recebido | I2: Tipo de Pgto | J2: Observação
G53: =IF(OR(C53 = "",C53="PENDENTE"), 0, IF(OR(C53<=B53,H53=1),F53,(F53*0.1966/100)*(C53-B53)+F53)) -> 0
G54: =IF(OR(C54 = "",C54="PENDENTE"), 0, IF(OR(C54<=B54,H54=1),F54,(F54*0.1966/100)*(C54-B54)+F54)) -> 0
G55: =IF(OR(C55 = "",C55="PENDENTE"), 0, IF(OR(C55<=B55,H55=1),F55,(F55*0.1966/100)*(C55-B55)+F55)) -> 0
G56: =IF(OR(C56 = "",C56="PENDENTE"), 0, IF(OR(C56<=B56,H56=1),F56,(F56*0.1966/100)*(C56-B56)+F56)) -> 0
G57: =IF(OR(C57 = "",C57="PENDENTE"), 0, IF(OR(C57<=B57,H57=1),F57,(F57*0.1966/100)*(C57-B57)+F57)) -> 0
G58: =IF(OR(C58 = "",C58="PENDENTE"), 0, IF(OR(C58<=B58,H58=1),F58,(F58*0.1966/100)*(C58-B58)+F58)) -> 0
G59: =IF(OR(C59 = "",C59="PENDENTE"), 0, IF(OR(C59<=B59,H59=1),F59,(F59*0.1966/100)*(C59-B59)+F59)) -> 0
G60: =IF(OR(C60 = "",C60="PENDENTE"), 0, IF(OR(C60<=B60,H60=1),F60,(F60*0.1966/100)*(C60-B60)+F60)) -> 0
G61: =IF(OR(C61 = "",C61="PENDENTE"), 0, IF(OR(C61<=B61,H61=1),F61,(F61*0.1966/100)*(C61-B61)+F61)) -> 0
G62: =IF(OR(C62 = "",C62="PENDENTE"), 0, IF(OR(C62<=B62,H62=1),F62,(F62*0.1966/100)*(C62-B62)+F62)) -> 0
G63: =IF(OR(C63 = "",C63="PENDENTE"), 0, IF(OR(C63<=B63,H63=1),F63,(F63*0.1966/100)*(C63-B63)+F63)) -> 0
G64: =IF(OR(C64 = "",C64="PENDENTE"), 0, IF(OR(C64<=B64,H64=1),F64,(F64*0.1966/100)*(C64-B64)+F64)) -> 0
... G76: =IF(OR(C76 = "",C76="PENDENTE"), 0, IF(OR(C76<=B76,H76=1),F76,(F76*0.1966/100)*(C76-B76)+F76)) -> 0
F77: =SUM(F3:F76) -> 0 | G77: =SUM(G3:G76) -> 0

Sheet JUN-26
A2: EMISSÃO | B2: Vencimento | C2: Recebido em | D2: NF | E2: CLIENTE | F2: Valor a Receber | G2: Valor Recebido | I2: Tipo de Pgto | J2: Observação
G53: =IF(OR(C53 = "",C53="PENDENTE"), 0, IF(OR(C53<=B53,H53=1),F53,(F53*0.1966/100)*(C53-B53)+F53)) -> 0
G54: =IF(OR(C54 = "",C54="PENDENTE"), 0, IF(OR(C54<=B54,H54=1),F54,(F54*0.1966/100)*(C54-B54)+F54)) -> 0
G55: =IF(OR(C55 = "",C55="PENDENTE"), 0, IF(OR(C55<=B55,H55=1),F55,(F55*0.1966/100)*(C55-B55)+F55)) -> 0
G56: =IF(OR(C56 = "",C56="PENDENTE"), 0, IF(OR(C56<=B56,H56=1),F56,(F56*0.1966/100)*(C56-B56)+F56)) -> 0
G57: =IF(OR(C57 = "",C57="PENDENTE"), 0, IF(OR(C57<=B57,H57=1),F57,(F57*0.1966/100)*(C57-B57)+F57)) -> 0
G58: =IF(OR(C58 = "",C58="PENDENTE"), 0, IF(OR(C58<=B58,H58=1),F58,(F58*0.1966/100)*(C58-B58)+F58)) -> 0
G59: =IF(OR(C59 = "",C59="PENDENTE"), 0, IF(OR(C59<=B59,H59=1),F59,(F59*0.1966/100)*(C59-B59)+F59)) -> 0
G60: =IF(OR(C60 = "",C60="PENDENTE"), 0, IF(OR(C60<=B60,H60=1),F60,(F60*0.1966/100)*(C60-B60)+F60)) -> 0
G61: =IF(OR(C61 = "",C61="PENDENTE"), 0, IF(OR(C61<=B61,H61=1),F61,(F61*0.1966/100)*(C61-B61)+F61)) -> 0
G62: =IF(OR(C62 = "",C62="PENDENTE"), 0, IF(OR(C62<=B62,H62=1),F62,(F62*0.1966/100)*(C62-B62)+F62)) -> 0
G63: =IF(OR(C63 = "",C63="PENDENTE"), 0, IF(OR(C63<=B63,H63=1),F63,(F63*0.1966/100)*(C63-B63)+F63)) -> 0
G64: =IF(OR(C64 = "",C64="PENDENTE"), 0, IF(OR(C64<=B64,H64=1),F64,(F64*0.1966/100)*(C64-B64)+F64)) -> 0
... G76: =IF(OR(C76 = "",C76="PENDENTE"), 0, IF(OR(C76<=B76,H76=1),F76,(F76*0.1966/100)*(C76-B76)+F76)) -> 0
F77: =SUM(F3:F76) -> 0 | G77: =SUM(G3:G76) -> 0
A599: 45925 | B599: 46028 | C599: 46024 | D599: 23441 | E599: NESTLE BRASIL | F599: 1872 | G599: 1872 | I599: DEP C/C
A627: 45947 | B627: 46037 | C627: 46037 | D627: 23468 | E627: BIMBO DO BRASIL LTDA | F627: 2566.25 | G627: 2566.25 | I627: DEP C/C
A656: 45959 | B656: 46068 | D656: 23497 | E656: BIMBO DO BRASIL LTDA | F656: 3082
A665: 45964 | B665: 46054 | D665: 23505 | E665: ROUSSELOT GELATINAS DO BRASIL LTDA | F665: 6220
A666: 45964 | B666: 46024 | C666: 46024 | D666: 23506 | E666: BAGLEY DO BRASIL | F666: 58040 | G666: 58040 | I666: BOLETO
A669: 45965 | B669: 46049 | D669: 23507 3 / 3 | E669: STARCLAVE IND E COM | F669: 4396.66
A674: 45967 | B674: 46051 | D674: 23513 | E674: SAINT-GOBAIN DO BRASIL | F674: 5862.02
A694: 45978 | B694: 46038 | C694: 46038 | D694: 23532 | E694: ROBERT BOSCH LIMITADA | F694: 1867 | G694: 1855.79 | I694: DEP C/C
A698: 45979 | B698: 46031 | C698: 46024 | D698: 23536 | E698: MARILAN ALIMENTOS LTDA | F698: 6004 | G698: 6004 | I698: DEP C/C
A701: 45979 | B701: 46038 | C701: 46038 | D701: 23538 2 / 3 | E701: ABC MANUTENÇÃO DE COMPRESSORES | F701: 5196.67 | G701: 5196.67 | I701: BOLETO
A702: 45979 | B702: 46069 | D702: 23538 3 / 3 | E702: ABC MANUTENÇÃO DE COMPRESSORES | F702: 5196.67
A709: 45986 | B709: 46052 | D709: 23545 | E709: CRISTALIA PROD QUIMICOS FARMACEUTICOS LTDA | F709: 9036 | I709: DEP C/C
A713: 45989 | B713: 46045 | D713: 23549 2 / 2 | E713: TERRAR IND E COM LTDA | F713: 3416
A714: 45992 | B714: 46034 | C714: 46034 | D714: 23550 | E714: MEXICHEM BRASIL | F714: 2822 | G714: 2822 | I714: BOLETO
A715: 45992 | B715: 46027 | C715: 45662 | D715: 23551 | E715: RICLAN S/A | F715: 6121.6 | G715: 6121.6 | I715: BOLETO
A719: 45993 | B719: 46028 | C719: 46028 | D719: 23555 | E719: RICLAN S/A | F719: 1186 | G719: 1186 | I719: BOLETO
A721: 45994 | B721: 46024 | C721: 46024 | D721: 23557 | E721: EUCATEX IND E COM LTDA | F721: 545 | G721: 545 | I721: DEP C/C
A723: 45995 | B723: 46023 | C723: 46023 | D723: 23559 | E723: CIRURGICA NEVES LTDA | F723: 3400 | G723: 3396 | I723: BOLETO
A724: 45995 | B724: 46023 | C724: 46024 | D724: 23560 | E724: COMBUSTOL FORNOS IND E COM LTDA | F724: 1046 | G724: 1046 | I724: BOLETO
A725: 45995 | B725: 46025 | C725: 46027 | D725: 23561 | E725: COMERCIAL BARRIGA VERDE LTDA | F725: 486 | G725: 486 | I725: BOLETO
A726: 45995 | B726: 46023 | C726: 46008 | D726: 23562 | E726: CHP CENTRAL HIDRAUICA E PNEUMATICA LTDA | F726: 446 | G726: 446 | I726: BOLETO
A727: 45996 | B727: 46030 | C727: 46030 | D727: 23563 | E727: ISOFLUID EQUIPTOS IND LTDA | F727: 1149 | G727: 1149 | I727: BOLETO
A728: 46000 | B728: 46035 | C728: 46035 | D728: 23564 | E728: RICLAN S/A | F728: 7890 | G728: 7890 | I728: BOLETO
A729: 46000 | B729: 46027 | C729: 46027 | D729: 23565 | E729: SUCOCITRICO CUTRALE LTDA | F729: 2526 | G729: 2526 | I729: DEP C/C
A730: 46000 | B730: 46030 | C730: 46031 | D730: 23566 | E730: DANISCO BRASIL LTDA | F730: 1385.35 | G730: 1385.35 | I730: DEP C/C
...

Sheet JUL-26
A2: EMISSÃO | B2: Vencimento | C2: Recebido em | D2: NF | E2: CLIENTE | F2: Valor a Receber | G2: Valor Recebido | I2: Tipo de Pgto | J2: Observação
G53: =IF(OR(C53 = "",C53="PENDENTE"), 0, IF(OR(C53<=B53,H53=1),F53,(F53*0.1966/100)*(C53-B53)+F53)) -> 0
G54: =IF(OR(C54 = "",C54="PENDENTE"), 0, IF(OR(C54<=B54,H54=1),F54,(F54*0.1966/100)*(C54-B54)+F54)) -> 0
G55: =IF(OR(C55 = "",C55="PENDENTE"), 0, IF(OR(C55<=B55,H55=1),F55,(F55*0.1966/100)*(C55-B55)+F55)) -> 0
G56: =IF(OR(C56 = "",C56="PENDENTE"), 0, IF(OR(C56<=B56,H56=1),F56,(F56*0.1966/100)*(C56-B56)+F56)) -> 0
G57: =IF(OR(C57 = "",C57="PENDENTE"), 0, IF(OR(C57<=B57,H57=1),F57,(F57*0.1966/100)*(C57-B57)+F57)) -> 0
G58: =IF(OR(C58 = "",C58="PENDENTE"), 0, IF(OR(C58<=B58,H58=1),F58,(F58*0.1966/100)*(C58-B58)+F58)) -> 0
G59: =IF(OR(C59 = "",C59="PENDENTE"), 0, IF(OR(C59<=B59,H59=1),F59,(F59*0.1966/100)*(C59-B59)+F59)) -> 0
G60: =IF(OR(C60 = "",C60="PENDENTE"), 0, IF(OR(C60<=B60,H60=1),F60,(F60*0.1966/100)*(C60-B60)+F60)) -> 0
G61: =IF(OR(C61 = "",C61="PENDENTE"), 0, IF(OR(C61<=B61,H61=1),F61,(F61*0.1966/100)*(C61-B61)+F61)) -> 0
G62: =IF(OR(C62 = "",C62="PENDENTE"), 0, IF(OR(C62<=B62,H62=1),F62,(F62*0.1966/100)*(C62-B62)+F62)) -> 0
G63: =IF(OR(C63 = "",C63="PENDENTE"), 0, IF(OR(C63<=B63,H63=1),F63,(F63*0.1966/100)*(C63-B63)+F63)) -> 0
G64: =IF(OR(C64 = "",C64="PENDENTE"), 0, IF(OR(C64<=B64,H64=1),F64,(F64*0.1966/100)*(C64-B64)+F64)) -> 0
... G76: =IF(OR(C76 = "",C76="PENDENTE"), 0, IF(OR(C76<=B76,H76=1),F76,(F76*0.1966/100)*(C76-B76)+F76)) -> 0
F77: =SUM(F3:F76) -> 0 | G77: =SUM(G3:G76) -> 0

Sheet AGO-26
A2: EMISSÃO | B2: Vencimento | C2: Recebido em | D2: NF | E2: CLIENTE | F2: Valor a Receber | G2: Valor Recebido | I2: Tipo de Pgto | J2: Observação
G53: =IF(OR(C53 = "",C53="PENDENTE"), 0, IF(OR(C53<=B53,H53=1),F53,(F53*0.1966/100)*(C53-B53)+F53)) -> 0
G54: =IF(OR(C54 = "",C54="PENDENTE"), 0, IF(OR(C54<=B54,H54=1),F54,(F54*0.1966/100)*(C54-B54)+F54)) -> 0
G55: =IF(OR(C55 = "",C55="PENDENTE"), 0, IF(OR(C55<=B55,H55=1),F55,(F55*0.1966/100)*(C55-B55)+F55)) -> 0
G56: =IF(OR(C56 = "",C56="PENDENTE"), 0, IF(OR(C56<=B56,H56=1),F56,(F56*0.1966/100)*(C56-B56)+F56)) -> 0
G57: =IF(OR(C57 = "",C57="PENDENTE"), 0, IF(OR(C57<=B57,H57=1),F57,(F57*0.1966/100)*(C57-B57)+F57)) -> 0
G58: =IF(OR(C58 = "",C58="PENDENTE"), 0, IF(OR(C58<=B58,H58=1),F58,(F58*0.1966/100)*(C58-B58)+F58)) -> 0
G59: =IF(OR(C59 = "",C59="PENDENTE"), 0, IF(OR(C59<=B59,H59=1),F59,(F59*0.1966/100)*(C59-B59)+F59)) -> 0
G60: =IF(OR(C60 = "",C60="PENDENTE"), 0, IF(OR(C60<=B60,H60=1),F60,(F60*0.1966/100)*(C60-B60)+F60)) -> 0
G61: =IF(OR(C61 = "",C61="PENDENTE"), 0, IF(OR(C61<=B61,H61=1),F61,(F61*0.1966/100)*(C61-B61)+F61)) -> 0
G62: =IF(OR(C62 = "",C62="PENDENTE"), 0, IF(OR(C62<=B62,H62=1),F62,(F62*0.1966/100)*(C62-B62)+F62)) -> 0
G63: =IF(OR(C63 = "",C63="PENDENTE"), 0, IF(OR(C63<=B63,H63=1),F63,(F63*0.1966/100)*(C63-B63)+F63)) -> 0
G64: =IF(OR(C64 = "",C64="PENDENTE"), 0, IF(OR(C64<=B64,H64=1),F64,(F64*0.1966/100)*(C64-B64)+F64)) -> 0
... G76: =IF(OR(C76 = "",C76="PENDENTE"), 0, IF(OR(C76<=B76,H76=1),F76,(F76*0.1966/100)*(C76-B76)+F76)) -> 0
F77: =SUM(F3:F76) -> 0 | G77: =SUM(G3:G76) -> 0

Sheet SET-26
A2: EMISSÃO | B2: Vencimento | C2: Recebido em | D2: NF | E2: CLIENTE | F2: Valor a Receber | G2: Valor Recebido | I2: Tipo de Pgto | J2: Observação
G53: =IF(OR(C53 = "",C53="PENDENTE"), 0, IF(OR(C53<=B53,H53=1),F53,(F53*0.1966/100)*(C53-B53)+F53)) -> 0
G54: =IF(OR(C54 = "",C54="PENDENTE"), 0, IF(OR(C54<=B54,H54=1),F54,(F54*0.1966/100)*(C54-B54)+F54)) -> 0
G55: =IF(OR(C55 = "",C55="PENDENTE"), 0, IF(OR(C55<=B55,H55=1),F55,(F55*0.1966/100)*(C55-B55)+F55)) -> 0
G56: =IF(OR(C56 = "",C56="PENDENTE"), 0, IF(OR(C56<=B56,H56=1),F56,(F56*0.1966/100)*(C56-B56)+F56)) -> 0
G57: =IF(OR(C57 = "",C57="PENDENTE"), 0, IF(OR(C57<=B57,H57=1),F57,(F57*0.1966/100)*(C57-B57)+F57)) -> 0
G58: =IF(OR(C58 = "",C58="PENDENTE"), 0, IF(OR(C58<=B58,H58=1),F58,(F58*0.1966/100)*(C58-B58)+F58)) -> 0
G59: =IF(OR(C59 = "",C59="PENDENTE"), 0, IF(OR(C59<=B59,H59=1),F59,(F59*0.1966/100)*(C59-B59)+F59)) -> 0
G60: =IF(OR(C60 = "",C60="PENDENTE"), 0, IF(OR(C60<=B60,H60=1),F60,(F60*0.1966/100)*(C60-B60)+F60)) -> 0
G61: =IF(OR(C61 = "",C61="PENDENTE"), 0, IF(OR(C61<=B61,H61=1),F61,(F61*0.1966/100)*(C61-B61)+F61)) -> 0
G62: =IF(OR(C62 = "",C62="PENDENTE"), 0, IF(OR(C62<=B62,H62=1),F62,(F62*0.1966/100)*(C62-B62)+F62)) -> 0
G63: =IF(OR(C63 = "",C63="PENDENTE"), 0, IF(OR(C63<=B63,H63=1),F63,(F63*0.1966/100)*(C63-B63)+F63)) -> 0
G64: =IF(OR(C64 = "",C64="PENDENTE"), 0, IF(OR(C64<=B64,H64=1),F64,(F64*0.1966/100)*(C64-B64)+F64)) -> 0
... G76: =IF(OR(C76 = "",C76="PENDENTE"), 0, IF(OR(C76<=B76,H76=1),F76,(F76*0.1966/100)*(C76-B76)+F76)) -> 0
F77: =SUM(F3:F76) -> 0 | G77: =SUM(G3:G76) -> 0

Sheet OUT-26
A2: EMISSÃO | B2: Vencimento | C2: Recebido em | D2: NF | E2: CLIENTE | F2: Valor a Receber | G2: Valor Recebido | I2: Tipo de Pgto | J2: Observação
G53: =IF(OR(C53 = "",C53="PENDENTE"), 0, IF(OR(C53<=B53,H53=1),F53,(F53*0.1966/100)*(C53-B53)+F53)) -> 0
G54: =IF(OR(C54 = "",C54="PENDENTE"), 0, IF(OR(C54<=B54,H54=1),F54,(F54*0.1966/100)*(C54-B54)+F54)) -> 0
G55: =IF(OR(C55 = "",C55="PENDENTE"), 0, IF(OR(C55<=B55,H55=1),F55,(F55*0.1966/100)*(C55-B55)+F55)) -> 0
G56: =IF(OR(C56 = "",C56="PENDENTE"), 0, IF(OR(C56<=B56,H56=1),F56,(F56*0.1966/100)*(C56-B56)+F56)) -> 0
G57: =IF(OR(C57 = "",C57="PENDENTE"), 0, IF(OR(C57<=B57,H57=1),F57,(F57*0.1966/100)*(C57-B57)+F57)) -> 0
G58: =IF(OR(C58 = "",C58="PENDENTE"), 0, IF(OR(C58<=B58,H58=1),F58,(F58*0.1966/100)*(C58-B58)+F58)) -> 0
G59: =IF(OR(C59 = "",C59="PENDENTE"), 0, IF(OR(C59<=B59,H59=1),F59,(F59*0.1966/100)*(C59-B59)+F59)) -> 0
G60: =IF(OR(C60 = "",C60="PENDENTE"), 0, IF(OR(C60<=B60,H60=1),F60,(F60*0.1966/100)*(C60-B60)+F60)) -> 0
G61: =IF(OR(C61 = "",C61="PENDENTE"), 0, IF(OR(C61<=B61,H61=1),F61,(F61*0.1966/100)*(C61-B61)+F61)) -> 0
G62: =IF(OR(C62 = "",C62="PENDENTE"), 0, IF(OR(C62<=B62,H62=1),F62,(F62*0.1966/100)*(C62-B62)+F62)) -> 0
G63: =IF(OR(C63 = "",C63="PENDENTE"), 0, IF(OR(C63<=B63,H63=1),F63,(F63*0.1966/100)*(C63-B63)+F63)) -> 0
G64: =IF(OR(C64 = "",C64="PENDENTE"), 0, IF(OR(C64<=B64,H64=1),F64,(F64*0.1966/100)*(C64-B64)+F64)) -> 0
... G76: =IF(OR(C76 = "",C76="PENDENTE"), 0, IF(OR(C76<=B76,H76=1),F76,(F76*0.1966/100)*(C76-B76)+F76)) -> 0
F77: =SUM(F3:F76) -> 0 | G77: =SUM(G3:G76) -> 0

Sheet NOV-26
A2: EMISSÃO | B2: Vencimento | C2: Recebido em | D2: NF | E2: CLIENTE | F2: Valor a Receber | G2: Valor Recebido | I2: Tipo de Pgto | J2: Observação
G53: =IF(OR(C53 = "",C53="PENDENTE"), 0, IF(OR(C53<=B53,H53=1),F53,(F53*0.1966/100)*(C53-B53)+F53)) -> 0
G54: =IF(OR(C54 = "",C54="PENDENTE"), 0, IF(OR(C54<=B54,H54=1),F54,(F54*0.1966/100)*(C54-B54)+F54)) -> 0
G55: =IF(OR(C55 = "",C55="PENDENTE"), 0, IF(OR(C55<=B55,H55=1),F55,(F55*0.1966/100)*(C55-B55)+F55)) -> 0
G56: =IF(OR(C56 = "",C56="PENDENTE"), 0, IF(OR(C56<=B56,H56=1),F56,(F56*0.1966/100)*(C56-B56)+F56)) -> 0
G57: =IF(OR(C57 = "",C57="PENDENTE"), 0, IF(OR(C57<=B57,H57=1),F57,(F57*0.1966/100)*(C57-B57)+F57)) -> 0
G58: =IF(OR(C58 = "",C58="PENDENTE"), 0, IF(OR(C58<=B58,H58=1),F58,(F58*0.1966/100)*(C58-B58)+F58)) -> 0
G59: =IF(OR(C59 = "",C59="PENDENTE"), 0, IF(OR(C59<=B59,H59=1),F59,(F59*0.1966/100)*(C59-B59)+F59)) -> 0
G60: =IF(OR(C60 = "",C60="PENDENTE"), 0, IF(OR(C60<=B60,H60=1),F60,(F60*0.1966/100)*(C60-B60)+F60)) -> 0
G61: =IF(OR(C61 = "",C61="PENDENTE"), 0, IF(OR(C61<=B61,H61=1),F61,(F61*0.1966/100)*(C61-B61)+F61)) -> 0
G62: =IF(OR(C62 = "",C62="PENDENTE"), 0, IF(OR(C62<=B62,H62=1),F62,(F62*0.1966/100)*(C62-B62)+F62)) -> 0
G63: =IF(OR(C63 = "",C63="PENDENTE"), 0, IF(OR(C63<=B63,H63=1),F63,(F63*0.1966/100)*(C63-B63)+F63)) -> 0
G64: =IF(OR(C64 = "",C64="PENDENTE"), 0, IF(OR(C64<=B64,H64=1),F64,(F64*0.1966/100)*(C64-B64)+F64)) -> 0
... G76: =IF(OR(C76 = "",C76="PENDENTE"), 0, IF(OR(C76<=B76,H76=1),F76,(F76*0.1966/100)*(C76-B76)+F76)) -> 0
F77: =SUM(F3:F76) -> 0 | G77: =SUM(G3:G76) -> 0

Sheet DEZ-26
A2: EMISSÃO | B2: Vencimento | C2: Recebido em | D2: NF | E2: CLIENTE | F2: Valor a Receber | G2: Valor Recebido | I2: Tipo de Pgto | J2: Observação
G53: =IF(OR(C53 = "",C53="PENDENTE"), 0, IF(OR(C53<=B53,H53=1),F53,(F53*0.1966/100)*(C53-B53)+F53)) -> 0
G54: =IF(OR(C54 = "",C54="PENDENTE"), 0, IF(OR(C54<=B54,H54=1),F54,(F54*0.1966/100)*(C54-B54)+F54)) -> 0
G55: =IF(OR(C55 = "",C55="PENDENTE"), 0, IF(OR(C55<=B55,H55=1),F55,(F55*0.1966/100)*(C55-B55)+F55)) -> 0
G56: =IF(OR(C56 = "",C56="PENDENTE"), 0, IF(OR(C56<=B56,H56=1),F56,(F56*0.1966/100)*(C56-B56)+F56)) -> 0
G57: =IF(OR(C57 = "",C57="PENDENTE"), 0, IF(OR(C57<=B57,H57=1),F57,(F57*0.1966/100)*(C57-B57)+F57)) -> 0
G58: =IF(OR(C58 = "",C58="PENDENTE"), 0, IF(OR(C58<=B58,H58=1),F58,(F58*0.1966/100)*(C58-B58)+F58)) -> 0
G59: =IF(OR(C59 = "",C59="PENDENTE"), 0, IF(OR(C59<=B59,H59=1),F59,(F59*0.1966/100)*(C59-B59)+F59)) -> 0
G60: =IF(OR(C60 = "",C60="PENDENTE"), 0, IF(OR(C60<=B60,H60=1),F60,(F60*0.1966/100)*(C60-B60)+F60)) -> 0
G61: =IF(OR(C61 = "",C61="PENDENTE"), 0, IF(OR(C61<=B61,H61=1),F61,(F61*0.1966/100)*(C61-B61)+F61)) -> 0
G62: =IF(OR(C62 = "",C62="PENDENTE"), 0, IF(OR(C62<=B62,H62=1),F62,(F62*0.1966/100)*(C62-B62)+F62)) -> 0
G63: =IF(OR(C63 = "",C63="PENDENTE"), 0, IF(OR(C63<=B63,H63=1),F63,(F63*0.1966/100)*(C63-B63)+F63)) -> 0
G64: =IF(OR(C64 = "",C64="PENDENTE"), 0, IF(OR(C64<=B64,H64=1),F64,(F64*0.1966/100)*(C64-B64)+F64)) -> 0
... G76: =IF(OR(C76 = "",C76="PENDENTE"), 0, IF(OR(C76<=B76,H76=1),F76,(F76*0.1966/100)*(C76-B76)+F76)) -> 0
F77: =SUM(F3:F76) -> 0 | G77: =SUM(G3:G76) -> 0

Sheet BD
B1: EMISSÃO | C1: Vencimento | D1: Recebido em | E1: NF | F1: CLIENTE | G1: FATURAMENTO | H1: V. Recebido | I1: MÊS FAT | J1: MÊS RECEB | K1: PREVISÃO | L1: MÊS PREV. | M1: AJ | N1: STATUS | O1: EMISSÃO | P1: VENCIMENTO | Q1: NFE | R1: CLIENTE | S1: VALOR | T1: DIAS
B2: ='JAN-26'!A3 -> 0 | C2: ='JAN-26'!B3 -> 0 | D2: ='JAN-26'!C3 -> 0 | E2: ='JAN-26'!D3 -> 0 | F2: ='JAN-26'!E3 -> 0 | G2: ='JAN-26'!F3 -> 0 | H2: =IF(OR(D2 = "",D2="PENDENTE"), 0, IF(OR(D2<=C2,M2=1),G2,(G2*0.1966/100)*(D2-C2)+G2)) -> 0 | I2: JAN | J2: =IF(OR(D2="PENDENTE", D2=0, D2=""), "", UPPER(TEXT(D2, "mmm"))) | K2: =IF(OR(D2="PENDENTE", D2="", D2=0, D2=DATE(1900,1,0)), G2, 0) -> 0 | L2: =IF(K2>0, UPPER(TEXT(C2, "mmm")), "") | M2: ='JAN-26'!H3 -> 0 | N2: =IF(BD!$C2="","",IF(AND(TODAY()>BD!$C2,OR(BD!$D2="PENDENTE",BD!$D2="")),"VENCIDO","")) | O2: =IF(N2 = "VENCIDO",BD!$B2,"") | P2: =IF(N2 = "VENCIDO",BD!$C2,"") | Q2: =IF(N2 = "VENCIDO",BD!$E2,"") | R2: =IF(N2 = "VENCIDO",BD!$F2,"") | S2: =IF(N2 = "VENCIDO",BD!$G2,"") | T2: =IF(AND(TODAY()>BD!$C2, OR(BD!$D2="PENDENTE", BD!$D2="")), TODAY()-BD!$C2, "")
B3: ='JAN-26'!A4 -> 0 | C3: ='JAN-26'!B4 -> 0 | D3: ='JAN-26'!C4 -> 0 | E3: ='JAN-26'!D4 -> 0 | F3: ='JAN-26'!E4 -> 0 | G3: ='JAN-26'!F4 -> 0 | H3: =IF(OR(D3 = "",D3="PENDENTE"), 0, IF(OR(D3<=C3,M3=1),G3,(G3*0.1966/100)*(D3-C3)+G3)) -> 0 | I3: JAN | J3: =IF(OR(D3="PENDENTE", D3=0, D3=""), "", UPPER(TEXT(D3, "mmm"))) | K3: =IF(OR(D3="PENDENTE", D3="", D3=0, D3=DATE(1900,1,0)), G3, 0) -> 0 | L3: =IF(K3>0, UPPER(TEXT(C3, "mmm")), "") | M3: ='JAN-26'!H4 -> 0 | N3: =IF(BD!$C3="","",IF(AND(TODAY()>BD!$C3,OR(BD!$D3="PENDENTE",BD!$D3="")),"VENCIDO","")) | O3: =IF(N3 = "VENCIDO",BD!$B3,"") | P3: =IF(N3 = "VENCIDO",BD!$C3,"") | Q3: =IF(N3 = "VENCIDO",BD!$E3,"") | R3: =IF(N3 = "VENCIDO",BD!$F3,"") | S3: =IF(N3 = "VENCIDO",BD!$G3,"") | T3: =IF(AND(TODAY()>BD!$C3, OR(BD!$D3="PENDENTE", BD!$D3="")), TODAY()-BD!$C3, "")
B4: ='JAN-26'!A5 -> 0 | C4: ='JAN-26'!B5 -> 0 | D4: ='JAN-26'!C5 -> 0 | E4: ='JAN-26'!D5 -> 0 | F4: ='JAN-26'!E5 -> 0 | G4: ='JAN-26'!F5 -> 0 | H4: =IF(OR(D4 = "",D4="PENDENTE"), 0, IF(OR(D4<=C4,M4=1),G4,(G4*0.1966/100)*(D4-C4)+G4)) -> 0 | I4: JAN | J4: =IF(OR(D4="PENDENTE", D4=0, D4=""), "", UPPER(TEXT(D4, "mmm"))) | K4: =IF(OR(D4="PENDENTE", D4="", D4=0, D4=DATE(1900,1,0)), G4, 0) -> 0 | L4: =IF(K4>0, UPPER(TEXT(C4, "mmm")), "") | M4: ='JAN-26'!H5 -> 0 | N4: =IF(BD!$C4="","",IF(AND(TODAY()>BD!$C4,OR(BD!$D4="PENDENTE",BD!$D4="")),"VENCIDO","")) | O4: =IF(N4 = "VENCIDO",BD!$B4,"") | P4: =IF(N4 = "VENCIDO",BD!$C4,"") | Q4: =IF(N4 = "VENCIDO",BD!$E4,"") | R4: =IF(N4 = "VENCIDO",BD!$F4,"") | S4: =IF(N4 = "VENCIDO",BD!$G4,"") | T4: =IF(AND(TODAY()>BD!$C4, OR(BD!$D4="PENDENTE", BD!$D4="")), TODAY()-BD!$C4, "")
B5: ='JAN-26'!A6 -> 0 | C5: ='JAN-26'!B6 -> 0 | D5: ='JAN-26'!C6 -> 0 | E5: ='JAN-26'!D6 -> 0 | F5: ='JAN-26'!E6 -> 0 | G5: ='JAN-26'!F6 -> 0 | H5: =IF(OR(D5 = "",D5="PENDENTE"), 0, IF(OR(D5<=C5,M5=1),G5,(G5*0.1966/100)*(D5-C5)+G5)) -> 0 | I5: JAN | J5: =IF(OR(D5="PENDENTE", D5=0, D5=""), "", UPPER(TEXT(D5, "mmm"))) | K5: =IF(OR(D5="PENDENTE", D5="", D5=0, D5=DATE(1900,1,0)), G5, 0) -> 0 | L5: =IF(K5>0, UPPER(TEXT(C5, "mmm")), "") | M5: ='JAN-26'!H6 -> 0 | N5: =IF(BD!$C5="","",IF(AND(TODAY()>BD!$C5,OR(BD!$D5="PENDENTE",BD!$D5="")),"VENCIDO","")) | O5: =IF(N5 = "VENCIDO",BD!$B5,"") | P5: =IF(N5 = "VENCIDO",BD!$C5,"") | Q5: =IF(N5 = "VENCIDO",BD!$E5,"") | R5: =IF(N5 = "VENCIDO",BD!$F5,"") | S5: =IF(N5 = "VENCIDO",BD!$G5,"") | T5: =IF(AND(TODAY()>BD!$C5, OR(BD!$D5="PENDENTE", BD!$D5="")), TODAY()-BD!$C5, "")
B6: ='JAN-26'!A7 -> 0 | C6: ='JAN-26'!B7 -> 0 | D6: ='JAN-26'!C7 -> 0 | E6: ='JAN-26'!D7 -> 0 | F6: ='JAN-26'!E7 -> 0 | G6: ='JAN-26'!F7 -> 0 | H6: =IF(OR(D6 = "",D6="PENDENTE"), 0, IF(OR(D6<=C6,M6=1),G6,(G6*0.1966/100)*(D6-C6)+G6)) -> 0 | I6: JAN | J6: =IF(OR(D6="PENDENTE", D6=0, D6=""), "", UPPER(TEXT(D6, "mmm"))) | K6: =IF(OR(D6="PENDENTE", D6="", D6=0, D6=DATE(1900,1,0)), G6, 0) -> 0 | L6: =IF(K6>0, UPPER(TEXT(C6, "mmm")), "") | M6: ='JAN-26'!H7 -> 0 | N6: =IF(BD!$C6="","",IF(AND(TODAY()>BD!$C6,OR(BD!$D6="PENDENTE",BD!$D6="")),"VENCIDO","")) | O6: =IF(N6 = "VENCIDO",BD!$B6,"") | P6: =IF(N6 = "VENCIDO",BD!$C6,"") | Q6: =IF(N6 = "VENCIDO",BD!$E6,"") | R6: =IF(N6 = "VENCIDO",BD!$F6,"") | S6: =IF(N6 = "VENCIDO",BD!$G6,"") | T6: =IF(AND(TODAY()>BD!$C6, OR(BD!$D6="PENDENTE", BD!$D6="")), TODAY()-BD!$C6, "")
B7: ='JAN-26'!A8 -> 0 | C7: ='JAN-26'!B8 -> 0 | D7: ='JAN-26'!C8 -> 0 | E7: ='JAN-26'!D8 -> 0 | F7: ='JAN-26'!E8 -> 0 | G7: ='JAN-26'!F8 -> 0 | H7: =IF(OR(D7 = "",D7="PENDENTE"), 0, IF(OR(D7<=C7,M7=1),G7,(G7*0.1966/100)*(D7-C7)+G7)) -> 0 | I7: JAN | J7: =IF(OR(D7="PENDENTE", D7=0, D7=""), "", UPPER(TEXT(D7, "mmm"))) | K7: =IF(OR(D7="PENDENTE", D7="", D7=0, D7=DATE(1900,1,0)), G7, 0) -> 0 | L7: =IF(K7>0, UPPER(TEXT(C7, "mmm")), "") | M7: ='JAN-26'!H8 -> 0 | N7: =IF(BD!$C7="","",IF(AND(TODAY()>BD!$C7,OR(BD!$D7="PENDENTE",BD!$D7="")),"VENCIDO","")) | O7: =IF(N7 = "VENCIDO",BD!$B7,"") | P7: =IF(N7 = "VENCIDO",BD!$C7,"") | Q7: =IF(N7 = "VENCIDO",BD!$E7,"") | R7: =IF(N7 = "VENCIDO",BD!$F7,"") | S7: =IF(N7 = "VENCIDO",BD!$G7,"") | T7: =IF(AND(TODAY()>BD!$C7, OR(BD!$D7="PENDENTE", BD!$D7="")), TODAY()-BD!$C7, "")
B8: ='JAN-26'!A9 -> 0 | C8: ='JAN-26'!B9 -> 0 | D8: ='JAN-26'!C9 -> 0 | E8: ='JAN-26'!D9 -> 0 | F8: ='JAN-26'!E9 -> 0 | G8: ='JAN-26'!F9 -> 0 | H8: =IF(OR(D8 = "",D8="PENDENTE"), 0, IF(OR(D8<=C8,M8=1),G8,(G8*0.1966/100)*(D8-C8)+G8)) -> 0 | I8: JAN | J8: =IF(OR(D8="PENDENTE", D8=0, D8=""), "", UPPER(TEXT(D8, "mmm"))) | K8: =IF(OR(D8="PENDENTE", D8="", D8=0, D8=DATE(1900,1,0)), G8, 0) -> 0 | L8: =IF(K8>0, UPPER(TEXT(C8, "mmm")), "") | M8: ='JAN-26'!H9 -> 0 | N8: =IF(BD!$C8="","",IF(AND(TODAY()>BD!$C8,OR(BD!$D8="PENDENTE",BD!$D8="")),"VENCIDO","")) | O8: =IF(N8 = "VENCIDO",BD!$B8,"") | P8: =IF(N8 = "VENCIDO",BD!$C8,"") | Q8: =IF(N8 = "VENCIDO",BD!$E8,"") | R8: =IF(N8 = "VENCIDO",BD!$F8,"") | S8: =IF(N8 = "VENCIDO",BD!$G8,"") | T8: =IF(AND(TODAY()>BD!$C8, OR(BD!$D8="PENDENTE", BD!$D8="")), TODAY()-BD!$C8, "")
B9: ='JAN-26'!A10 -> 0 | C9: ='JAN-26'!B10 -> 0 | D9: ='JAN-26'!C10 -> 0 | E9: ='JAN-26'!D10 -> 0 | F9: ='JAN-26'!E10 -> 0 | G9: ='JAN-26'!F10 -> 0 | H9: =IF(OR(D9 = "",D9="PENDENTE"), 0, IF(OR(D9<=C9,M9=1),G9,(G9*0.1966/100)*(D9-C9)+G9)) -> 0 | I9: JAN | J9: =IF(OR(D9="PENDENTE", D9=0, D9=""), "", UPPER(TEXT(D9, "mmm"))) | K9: =IF(OR(D9="PENDENTE", D9="", D9=0, D9=DATE(1900,1,0)), G9, 0) -> 0 | L9: =IF(K9>0, UPPER(TEXT(C9, "mmm")), "") | M9: ='JAN-26'!H10 -> 0 | N9: =IF(BD!$C9="","",IF(AND(TODAY()>BD!$C9,OR(BD!$D9="PENDENTE",BD!$D9="")),"VENCIDO","")) | O9: =IF(N9 = "VENCIDO",BD!$B9,"") | P9: =IF(N9 = "VENCIDO",BD!$C9,"") | Q9: =IF(N9 = "VENCIDO",BD!$E9,"") | R9: =IF(N9 = "VENCIDO",BD!$F9,"") | S9: =IF(N9 = "VENCIDO",BD!$G9,"") | T9: =IF(AND(TODAY()>BD!$C9, OR(BD!$D9="PENDENTE", BD!$D9="")), TODAY()-BD!$C9, "")
B10: ='JAN-26'!A11 -> 0 | C10: ='JAN-26'!B11 -> 0 | D10: ='JAN-26'!C11 -> 0 | E10: ='JAN-26'!D11 -> 0 | F10: ='JAN-26'!E11 -> 0 | G10: ='JAN-26'!F11 -> 0 | H10: =IF(OR(D10 = "",D10="PENDENTE"), 0, IF(OR(D10<=C10,M10=1),G10,(G10*0.1966/100)*(D10-C10)+G10)) -> 0 | I10: JAN | J10: =IF(OR(D10="PENDENTE", D10=0, D10=""), "", UPPER(TEXT(D10, "mmm"))) | K10: =IF(OR(D10="PENDENTE", D10="", D10=0, D10=DATE(1900,1,0)), G10, 0) -> 0 | L10: =IF(K10>0, UPPER(TEXT(C10, "mmm")), "") | M10: ='JAN-26'!H11 -> 0 | N10: =IF(BD!$C10="","",IF(AND(TODAY()>BD!$C10,OR(BD!$D10="PENDENTE",BD!$D10="")),"VENCIDO","")) | O10: =IF(N10 = "VENCIDO",BD!$B10,"") | P10: =IF(N10 = "VENCIDO",BD!$C10,"") | Q10: =IF(N10 = "VENCIDO",BD!$E10,"") | R10: =IF(N10 = "VENCIDO",BD!$F10,"") | S10: =IF(N10 = "VENCIDO",BD!$G10,"") | T10: =IF(AND(TODAY()>BD!$C10, OR(BD!$D10="PENDENTE", BD!$D10="")), TODAY()-BD!$C10, "")
B11: ='JAN-26'!A12 -> 0 | C11: ='JAN-26'!B12 -> 0 | D11: ='JAN-26'!C12 -> 0 | E11: ='JAN-26'!D12 -> 0 | F11: ='JAN-26'!E12 -> 0 | G11: ='JAN-26'!F12 -> 0 | H11: =IF(OR(D11 = "",D11="PENDENTE"), 0, IF(OR(D11<=C11,M11=1),G11,(G11*0.1966/100)*(D11-C11)+G11)) -> 0 | I11: JAN | J11: =IF(OR(D11="PENDENTE", D11=0, D11=""), "", UPPER(TEXT(D11, "mmm"))) | K11: =IF(OR(D11="PENDENTE", D11="", D11=0, D11=DATE(1900,1,0)), G11, 0) -> 0 | L11: =IF(K11>0, UPPER(TEXT(C11, "mmm")), "") | M11: ='JAN-26'!H12 -> 0 | N11: =IF(BD!$C11="","",IF(AND(TODAY()>BD!$C11,OR(BD!$D11="PENDENTE",BD!$D11="")),"VENCIDO","")) | O11: =IF(N11 = "VENCIDO",BD!$B11,"") | P11: =IF(N11 = "VENCIDO",BD!$C11,"") | Q11: =IF(N11 = "VENCIDO",BD!$E11,"") | R11: =IF(N11 = "VENCIDO",BD!$F11,"") | S11: =IF(N11 = "VENCIDO",BD!$G11,"") | T11: =IF(AND(TODAY()>BD!$C11, OR(BD!$D11="PENDENTE", BD!$D11="")), TODAY()-BD!$C11, "")
B12: ='JAN-26'!A13 -> 0 | C12: ='JAN-26'!B13 -> 0 | D12: ='JAN-26'!C13 -> 0 | E12: ='JAN-26'!D13 -> 0 | F12: ='JAN-26'!E13 -> 0 | G12: ='JAN-26'!F13 -> 0 | H12: =IF(OR(D12 = "",D12="PENDENTE"), 0, IF(OR(D12<=C12,M12=1),G12,(G12*0.1966/100)*(D12-C12)+G12)) -> 0 | I12: JAN | J12: =IF(OR(D12="PENDENTE", D12=0, D12=""), "", UPPER(TEXT(D12, "mmm"))) | K12: =IF(OR(D12="PENDENTE", D12="", D12=0, D12=DATE(1900,1,0)), G12, 0) -> 0 | L12: =IF(K12>0, UPPER(TEXT(C12, "mmm")), "") | M12: ='JAN-26'!H13 -> 0 | N12: =IF(BD!$C12="","",IF(AND(TODAY()>BD!$C12,OR(BD!$D12="PENDENTE",BD!$D12="")),"VENCIDO","")) | O12: =IF(N12 = "VENCIDO",BD!$B12,"") | P12: =IF(N12 = "VENCIDO",BD!$C12,"") | Q12: =IF(N12 = "VENCIDO",BD!$E12,"") | R12: =IF(N12 = "VENCIDO",BD!$F12,"") | S12: =IF(N12 = "VENCIDO",BD!$G12,"") | T12: =IF(AND(TODAY()>BD!$C12, OR(BD!$D12="PENDENTE", BD!$D12="")), TODAY()-BD!$C12, "")
B13: ='JAN-26'!A14 -> 0 | C13: ='JAN-26'!B14 -> 0 | D13: ='JAN-26'!C14 -> 0 | E13: ='JAN-26'!D14 -> 0 | F13: ='JAN-26'!E14 -> 0 | G13: ='JAN-26'!F14 -> 0 | H13: =IF(OR(D13 = "",D13="PENDENTE"), 0, IF(OR(D13<=C13,M13=1),G13,(G13*0.1966/100)*(D13-C13)+G13)) -> 0 | I13: JAN | J13: =IF(OR(D13="PENDENTE", D13=0, D13=""), "", UPPER(TEXT(D13, "mmm"))) | K13: =IF(OR(D13="PENDENTE", D13="", D13=0, D13=DATE(1900,1,0)), G13, 0) -> 0 | L13: =IF(K13>0, UPPER(TEXT(C13, "mmm")), "") | M13: ='JAN-26'!H14 -> 0 | N13: =IF(BD!$C13="","",IF(AND(TODAY()>BD!$C13,OR(BD!$D13="PENDENTE",BD!$D13="")),"VENCIDO","")) | O13: =IF(N13 = "VENCIDO",BD!$B13,"") | P13: =IF(N13 = "VENCIDO",BD!$C13,"") | Q13: =IF(N13 = "VENCIDO",BD!$E13,"") | R13: =IF(N13 = "VENCIDO",BD!$F13,"") | S13: =IF(N13 = "VENCIDO",BD!$G13,"") | T13: =IF(AND(TODAY()>BD!$C13, OR(BD!$D13="PENDENTE", BD!$D13="")), TODAY()-BD!$C13, "")
... B75: ='JAN-26'!A76 -> 0 | C75: ='JAN-26'!B76 -> 0 | D75: ='JAN-26'!C76 -> 0 | E75: ='JAN-26'!D76 -> 0 | F75: ='JAN-26'!E76 -> 0 | G75: ='JAN-26'!F76 -> 0 | H75: =IF(OR(D75 = "",D75="PENDENTE"), 0, IF(OR(D75<=C75,M75=1),G75,(G75*0.1966/100)*(D75-C75)+G75)) -> 0 | I75: JAN | J75: =IF(OR(D75="PENDENTE", D75=0, D75=""), "", UPPER(TEXT(D75, "mmm"))) | K75: =IF(OR(D75="PENDENTE", D75="", D75=0, D75=DATE(1900,1,0)), G75, 0) -> 0 | L75: =IF(K75>0, UPPER(TEXT(C75, "mmm")), "") | M75: ='JAN-26'!H76 -> 0 | N75: =IF(BD!$C75="","",IF(AND(TODAY()>BD!$C75,OR(BD!$D75="PENDENTE",BD!$D75="")),"VENCIDO","")) | O75: =IF(N75 = "VENCIDO",BD!$B75,"") | P75: =IF(N75 = "VENCIDO",BD!$C75,"") | Q75: =IF(N75 = "VENCIDO",BD!$E75,"") | R75: =IF(N75 = "VENCIDO",BD!$F75,"") | S75: =IF(N75 = "VENCIDO",BD!$G75,"") | T75: =IF(AND(TODAY()>BD!$C75, OR(BD!$D75="PENDENTE", BD!$D75="")), TODAY()-BD!$C75, "")
B76: ='FEV-26'!A3 -> 0 | C76: ='FEV-26'!B3 -> 0 | D76: ='FEV-26'!C3 -> 0 | E76: ='FEV-26'!D3 -> 0 | F76: ='FEV-26'!E3 -> 0 | G76: ='FEV-26'!F3 -> 0 | H76: =IF(OR(D76 = "",D76="PENDENTE"), 0, IF(OR(D76<=C76,M76=1),G76,(G76*0.1966/100)*(D76-C76)+G76)) -> 0 | I76: FEV | J76: =IF(OR(D76="PENDENTE", D76=0, D76=""), "", UPPER(TEXT(D76, "mmm"))) | K76: =IF(OR(D76="PENDENTE", D76="", D76=0, D76=DATE(1900,1,0)), G76, 0) -> 0 | L76: =IF(K76>0, UPPER(TEXT(C76, "mmm")), "") | M76: ='FEV-26'!H3 -> 0 | N76: =IF(BD!$C76="","",IF(AND(TODAY()>BD!$C76,OR(BD!$D76="PENDENTE",BD!$D76="")),"VENCIDO","")) | O76: =IF(N76 = "VENCIDO",BD!$B76,"") | P76: =IF(N76 = "VENCIDO",BD!$C76,"") | Q76: =IF(N76 = "VENCIDO",BD!$E76,"") | R76: =IF(N76 = "VENCIDO",BD!$F76,"") | S76: =IF(N76 = "VENCIDO",BD!$G76,"") | T76: =IF(AND(TODAY()>BD!$C76, OR(BD!$D76="PENDENTE", BD!$D76="")), TODAY()-BD!$C76, "")
B77: ='FEV-26'!A4 -> 0 | C77: ='FEV-26'!B4 -> 0 | D77: ='FEV-26'!C4 -> 0 | E77: ='FEV-26'!D4 -> 0 | F77: ='FEV-26'!E4 -> 0 | G77: ='FEV-26'!F4 -> 0 | H77: =IF(OR(D77 = "",D77="PENDENTE"), 0, IF(OR(D77<=C77,M77=1),G77,(G77*0.1966/100)*(D77-C77)+G77)) -> 0 | I77: FEV | J77: =IF(OR(D77="PENDENTE", D77=0, D77=""), "", UPPER(TEXT(D77, "mmm"))) | K77: =IF(OR(D77="PENDENTE", D77="", D77=0, D77=DATE(1900,1,0)), G77, 0) -> 0 | L77: =IF(K77>0, UPPER(TEXT(C77, "mmm")), "") | M77: ='FEV-26'!H4 -> 0 | N77: =IF(BD!$C77="","",IF(AND(TODAY()>BD!$C77,OR(BD!$D77="PENDENTE",BD!$D77="")),"VENCIDO","")) | O77: =IF(N77 = "VENCIDO",BD!$B77,"") | P77: =IF(N77 = "VENCIDO",BD!$C77,"") | Q77: =IF(N77 = "VENCIDO",BD!$E77,"") | R77: =IF(N77 = "VENCIDO",BD!$F77,"") | S77: =IF(N77 = "VENCIDO",BD!$G77,"") | T77: =IF(AND(TODAY()>BD!$C77, OR(BD!$D77="PENDENTE", BD!$D77="")), TODAY()-BD!$C77, "")
B78: ='FEV-26'!A5 -> 0 | C78: ='FEV-26'!B5 -> 0 | D78: ='FEV-26'!C5 -> 0 | E78: ='FEV-26'!D5 -> 0 | F78: ='FEV-26'!E5 -> 0 | G78: ='FEV-26'!F5 -> 0 | H78: =IF(OR(D78 = "",D78="PENDENTE"), 0, IF(OR(D78<=C78,M78=1),G78,(G78*0.1966/100)*(D78-C78)+G78)) -> 0 | I78: FEV | J78: =IF(OR(D78="PENDENTE", D78=0, D78=""), "", UPPER(TEXT(D78, "mmm"))) | K78: =IF(OR(D78="PENDENTE", D78="", D78=0, D78=DATE(1900,1,0)), G78, 0) -> 0 | L78: =IF(K78>0, UPPER(TEXT(C78, "mmm")), "") | M78: ='FEV-26'!H5 -> 0 | N78: =IF(BD!$C78="","",IF(AND(TODAY()>BD!$C78,OR(BD!$D78="PENDENTE",BD!$D78="")),"VENCIDO","")) | O78: =IF(N78 = "VENCIDO",BD!$B78,"") | P78: =IF(N78 = "VENCIDO",BD!$C78,"") | Q78: =IF(N78 = "VENCIDO",BD!$E78,"") | R78: =IF(N78 = "VENCIDO",BD!$F78,"") | S78: =IF(N78 = "VENCIDO",BD!$G78,"") | T78: =IF(AND(TODAY()>BD!$C78, OR(BD!$D78="PENDENTE", BD!$D78="")), TODAY()-BD!$C78, "")
B79: ='FEV-26'!A6 -> 0 | C79: ='FEV-26'!B6 -> 0 | D79: ='FEV-26'!C6 -> 0 | E79: ='FEV-26'!D6 -> 0 | F79: ='FEV-26'!E6 -> 0 | G79: ='FEV-26'!F6 -> 0 | H79: =IF(OR(D79 = "",D79="PENDENTE"), 0, IF(OR(D79<=C79,M79=1),G79,(G79*0.1966/100)*(D79-C79)+G79)) -> 0 | I79: FEV | J79: =IF(OR(D79="PENDENTE", D79=0, D79=""), "", UPPER(TEXT(D79, "mmm"))) | K79: =IF(OR(D79="PENDENTE", D79="", D79=0, D79=DATE(1900,1,0)), G79, 0) -> 0 | L79: =IF(K79>0, UPPER(TEXT(C79, "mmm")), "") | M79: ='FEV-26'!H6 -> 0 | N79: =IF(BD!$C79="","",IF(AND(TODAY()>BD!$C79,OR(BD!$D79="PENDENTE",BD!$D79="")),"VENCIDO","")) | O79: =IF(N79 = "VENCIDO",BD!$B79,"") | P79: =IF(N79 = "VENCIDO",BD!$C79,"") | Q79: =IF(N79 = "VENCIDO",BD!$E79,"") | R79: =IF(N79 = "VENCIDO",BD!$F79,"") | S79: =IF(N79 = "VENCIDO",BD!$G79,"") | T79: =IF(AND(TODAY()>BD!$C79, OR(BD!$D79="PENDENTE", BD!$D79="")), TODAY()-BD!$C79, "")
B80: ='FEV-26'!A7 -> 0 | C80: ='FEV-26'!B7 -> 0 | D80: ='FEV-26'!C7 -> 0 | E80: ='FEV-26'!D7 -> 0 | F80: ='FEV-26'!E7 -> 0 | G80: ='FEV-26'!F7 -> 0 | H80: =IF(OR(D80 = "",D80="PENDENTE"), 0, IF(OR(D80<=C80,M80=1),G80,(G80*0.1966/100)*(D80-C80)+G80)) -> 0 | I80: FEV | J80: =IF(OR(D80="PENDENTE", D80=0, D80=""), "", UPPER(TEXT(D80, "mmm"))) | K80: =IF(OR(D80="PENDENTE", D80="", D80=0, D80=DATE(1900,1,0)), G80, 0) -> 0 | L80: =IF(K80>0, UPPER(TEXT(C80, "mmm")), "") | M80: ='FEV-26'!H7 -> 0 | N80: =IF(BD!$C80="","",IF(AND(TODAY()>BD!$C80,OR(BD!$D80="PENDENTE",BD!$D80="")),"VENCIDO","")) | O80: =IF(N80 = "VENCIDO",BD!$B80,"") | P80: =IF(N80 = "VENCIDO",BD!$C80,"") | Q80: =IF(N80 = "VENCIDO",BD!$E80,"") | R80: =IF(N80 = "VENCIDO",BD!$F80,"") | S80: =IF(N80 = "VENCIDO",BD!$G80,"") | T80: =IF(AND(TODAY()>BD!$C80, OR(BD!$D80="PENDENTE", BD!$D80="")), TODAY()-BD!$C80, "")
B81: ='FEV-26'!A8 -> 0 | C81: ='FEV-26'!B8 -> 0 | D81: ='FEV-26'!C8 -> 0 | E81: ='FEV-26'!D8 -> 0 | F81: ='FEV-26'!E8 -> 0 | G81: ='FEV-26'!F8 -> 0 | H81: =IF(OR(D81 = "",D81="PENDENTE"), 0, IF(OR(D81<=C81,M81=1),G81,(G81*0.1966/100)*(D81-C81)+G81)) -> 0 | I81: FEV | J81: =IF(OR(D81="PENDENTE", D81=0, D81=""), "", UPPER(TEXT(D81, "mmm"))) | K81: =IF(OR(D81="PENDENTE", D81="", D81=0, D81=DATE(1900,1,0)), G81, 0) -> 0 | L81: =IF(K81>0, UPPER(TEXT(C81, "mmm")), "") | M81: ='FEV-26'!H8 -> 0 | N81: =IF(BD!$C81="","",IF(AND(TODAY()>BD!$C81,OR(BD!$D81="PENDENTE",BD!$D81="")),"VENCIDO","")) | O81: =IF(N81 = "VENCIDO",BD!$B81,"") | P81: =IF(N81 = "VENCIDO",BD!$C81,"") | Q81: =IF(N81 = "VENCIDO",BD!$E81,"") | R81: =IF(N81 = "VENCIDO",BD!$F81,"") | S81: =IF(N81 = "VENCIDO",BD!$G81,"") | T81: =IF(AND(TODAY()>BD!$C81, OR(BD!$D81="PENDENTE", BD!$D81="")), TODAY()-BD!$C81, "")
B82: ='FEV-26'!A9 -> 0 | C82: ='FEV-26'!B9 -> 0 | D82: ='FEV-26'!C9 -> 0 | E82: ='FEV-26'!D9 -> 0 | F82: ='FEV-26'!E9 -> 0 | G82: ='FEV-26'!F9 -> 0 | H82: =IF(OR(D82 = "",D82="PENDENTE"), 0, IF(OR(D82<=C82,M82=1),G82,(G82*0.1966/100)*(D82-C82)+G82)) -> 0 | I82: FEV | J82: =IF(OR(D82="PENDENTE", D82=0, D82=""), "", UPPER(TEXT(D82, "mmm"))) | K82: =IF(OR(D82="PENDENTE", D82="", D82=0, D82=DATE(1900,1,0)), G82, 0) -> 0 | L82: =IF(K82>0, UPPER(TEXT(C82, "mmm")), "") | M82: ='FEV-26'!H9 -> 0 | N82: =IF(BD!$C82="","",IF(AND(TODAY()>BD!$C82,OR(BD!$D82="PENDENTE",BD!$D82="")),"VENCIDO","")) | O82: =IF(N82 = "VENCIDO",BD!$B82,"") | P82: =IF(N82 = "VENCIDO",BD!$C82,"") | Q82: =IF(N82 = "VENCIDO",BD!$E82,"") | R82: =IF(N82 = "VENCIDO",BD!$F82,"") | S82: =IF(N82 = "VENCIDO",BD!$G82,"") | T82: =IF(AND(TODAY()>BD!$C82, OR(BD!$D82="PENDENTE", BD!$D82="")), TODAY()-BD!$C82, "")
B83: ='FEV-26'!A10 -> 0 | C83: ='FEV-26'!B10 -> 0 | D83: ='FEV-26'!C10 -> 0 | E83: ='FEV-26'!D10 -> 0 | F83: ='FEV-26'!E10 -> 0 | G83: ='FEV-26'!F10 -> 0 | H83: =IF(OR(D83 = "",D83="PENDENTE"), 0, IF(OR(D83<=C83,M83=1),G83,(G83*0.1966/100)*(D83-C83)+G83)) -> 0 | I83: FEV | J83: =IF(OR(D83="PENDENTE", D83=0, D83=""), "", UPPER(TEXT(D83, "mmm"))) | K83: =IF(OR(D83="PENDENTE", D83="", D83=0, D83=DATE(1900,1,0)), G83, 0) -> 0 | L83: =IF(K83>0, UPPER(TEXT(C83, "mmm")), "") | M83: ='FEV-26'!H10 -> 0 | N83: =IF(BD!$C83="","",IF(AND(TODAY()>BD!$C83,OR(BD!$D83="PENDENTE",BD!$D83="")),"VENCIDO","")) | O83: =IF(N83 = "VENCIDO",BD!$B83,"") | P83: =IF(N83 = "VENCIDO",BD!$C83,"") | Q83: =IF(N83 = "VENCIDO",BD!$E83,"") | R83: =IF(N83 = "VENCIDO",BD!$F83,"") | S83: =IF(N83 = "VENCIDO",BD!$G83,"") | T83: =IF(AND(TODAY()>BD!$C83, OR(BD!$D83="PENDENTE", BD!$D83="")), TODAY()-BD!$C83, "")
B84: ='FEV-26'!A11 -> 0 | C84: ='FEV-26'!B11 -> 0 | D84: ='FEV-26'!C11 -> 0 | E84: ='FEV-26'!D11 -> 0 | F84: ='FEV-26'!E11 -> 0 | G84: ='FEV-26'!F11 -> 0 | H84: =IF(OR(D84 = "",D84="PENDENTE"), 0, IF(OR(D84<=C84,M84=1),G84,(G84*0.1966/100)*(D84-C84)+G84)) -> 0 | I84: FEV | J84: =IF(OR(D84="PENDENTE", D84=0, D84=""), "", UPPER(TEXT(D84, "mmm"))) | K84: =IF(OR(D84="PENDENTE", D84="", D84=0, D84=DATE(1900,1,0)), G84, 0) -> 0 | L84: =IF(K84>0, UPPER(TEXT(C84, "mmm")), "") | M84: ='FEV-26'!H11 -> 0 | N84: =IF(BD!$C84="","",IF(AND(TODAY()>BD!$C84,OR(BD!$D84="PENDENTE",BD!$D84="")),"VENCIDO","")) | O84: =IF(N84 = "VENCIDO",BD!$B84,"") | P84: =IF(N84 = "VENCIDO",BD!$C84,"") | Q84: =IF(N84 = "VENCIDO",BD!$E84,"") | R84: =IF(N84 = "VENCIDO",BD!$F84,"") | S84: =IF(N84 = "VENCIDO",BD!$G84,"") | T84: =IF(AND(TODAY()>BD!$C84, OR(BD!$D84="PENDENTE", BD!$D84="")), TODAY()-BD!$C84, "")
B85: ='FEV-26'!A12 -> 0 | C85: ='FEV-26'!B12 -> 0 | D85: ='FEV-26'!C12 -> 0 | E85: ='FEV-26'!D12 -> 0 | F85: ='FEV-26'!E12 -> 0 | G85: ='FEV-26'!F12 -> 0 | H85: =IF(OR(D85 = "",D85="PENDENTE"), 0, IF(OR(D85<=C85,M85=1),G85,(G85*0.1966/100)*(D85-C85)+G85)) -> 0 | I85: FEV | J85: =IF(OR(D85="PENDENTE", D85=0, D85=""), "", UPPER(TEXT(D85, "mmm"))) | K85: =IF(OR(D85="PENDENTE", D85="", D85=0, D85=DATE(1900,1,0)), G85, 0) -> 0 | L85: =IF(K85>0, UPPER(TEXT(C85, "mmm")), "") | M85: ='FEV-26'!H12 -> 0 | N85: =IF(BD!$C85="","",IF(AND(TODAY()>BD!$C85,OR(BD!$D85="PENDENTE",BD!$D85="")),"VENCIDO","")) | O85: =IF(N85 = "VENCIDO",BD!$B85,"") | P85: =IF(N85 = "VENCIDO",BD!$C85,"") | Q85: =IF(N85 = "VENCIDO",BD!$E85,"") | R85: =IF(N85 = "VENCIDO",BD!$F85,"") | S85: =IF(N85 = "VENCIDO",BD!$G85,"") | T85: =IF(AND(TODAY()>BD!$C85, OR(BD!$D85="PENDENTE", BD!$D85="")), TODAY()-BD!$C85, "")
B86: ='FEV-26'!A13 -> 0 | C86: ='FEV-26'!B13 -> 0 | D86: ='FEV-26'!C13 -> 0 | E86: ='FEV-26'!D13 -> 0 | F86: ='FEV-26'!E13 -> 0 | G86: ='FEV-26'!F13 -> 0 | H86: =IF(OR(D86 = "",D86="PENDENTE"), 0, IF(OR(D86<=C86,M86=1),G86,(G86*0.1966/100)*(D86-C86)+G86)) -> 0 | I86: FEV | J86: =IF(OR(D86="PENDENTE", D86=0, D86=""), "", UPPER(TEXT(D86, "mmm"))) | K86: =IF(OR(D86="PENDENTE", D86="", D86=0, D86=DATE(1900,1,0)), G86, 0) -> 0 | L86: =IF(K86>0, UPPER(TEXT(C86, "mmm")), "") | M86: ='FEV-26'!H13 -> 0 | N86: =IF(BD!$C86="","",IF(AND(TODAY()>BD!$C86,OR(BD!$D86="PENDENTE",BD!$D86="")),"VENCIDO","")) | O86: =IF(N86 = "VENCIDO",BD!$B86,"") | P86: =IF(N86 = "VENCIDO",BD!$C86,"") | Q86: =IF(N86 = "VENCIDO",BD!$E86,"") | R86: =IF(N86 = "VENCIDO",BD!$F86,"") | S86: =IF(N86 = "VENCIDO",BD!$G86,"") | T86: =IF(AND(TODAY()>BD!$C86, OR(BD!$D86="PENDENTE", BD!$D86="")), TODAY()-BD!$C86, "")
B87: ='FEV-26'!A14 -> 0 | C87: ='FEV-26'!B14 -> 0 | D87: ='FEV-26'!C14 -> 0 | E87: ='FEV-26'!D14 -> 0 | F87: ='FEV-26'!E14 -> 0 | G87: ='FEV-26'!F14 -> 0 | H87: =IF(OR(D87 = "",D87="PENDENTE"), 0, IF(OR(D87<=C87,M87=1),G87,(G87*0.1966/100)*(D87-C87)+G87)) -> 0 | I87: FEV | J87: =IF(OR(D87="PENDENTE", D87=0, D87=""), "", UPPER(TEXT(D87, "mmm"))) | K87: =IF(OR(D87="PENDENTE", D87="", D87=0, D87=DATE(1900,1,0)), G87, 0) -> 0 | L87: =IF(K87>0, UPPER(TEXT(C87, "mmm")), "") | M87: ='FEV-26'!H14 -> 0 | N87: =IF(BD!$C87="","",IF(AND(TODAY()>BD!$C87,OR(BD!$D87="PENDENTE",BD!$D87="")),"VENCIDO","")) | O87: =IF(N87 = "VENCIDO",BD!$B87,"") | P87: =IF(N87 = "VENCIDO",BD!$C87,"") | Q87: =IF(N87 = "VENCIDO",BD!$E87,"") | R87: =IF(N87 = "VENCIDO",BD!$F87,"") | S87: =IF(N87 = "VENCIDO",BD!$G87,"") | T87: =IF(AND(TODAY()>BD!$C87, OR(BD!$D87="PENDENTE", BD!$D87="")), TODAY()-BD!$C87, "")
... B149: ='FEV-26'!A76 -> 0 | C149: ='FEV-26'!B76 -> 0 | D149: ='FEV-26'!C76 -> 0 | E149: ='FEV-26'!D76 -> 0 | F149: ='FEV-26'!E76 -> 0 | G149: ='FEV-26'!F76 -> 0 | H149: =IF(OR(D149 = "",D149="PENDENTE"), 0, IF(OR(D149<=C149,M149=1),G149,(G149*0.1966/100)*(D149-C149)+G149)) -> 0 | I149: FEV | J149: =IF(OR(D149="PENDENTE", D149=0, D149=""), "", UPPER(TEXT(D149, "mmm"))) | K149: =IF(OR(D149="PENDENTE", D149="", D149=0, D149=DATE(1900,1,0)), G149, 0) -> 0 | L149: =IF(K149>0, UPPER(TEXT(C149, "mmm")), "") | M149: ='FEV-26'!H76 -> 0 | N149: =IF(BD!$C149="","",IF(AND(TODAY()>BD!$C149,OR(BD!$D149="PENDENTE",BD!$D149="")),"VENCIDO","")) | O149: =IF(N149 = "VENCIDO",BD!$B149,"") | P149: =IF(N149 = "VENCIDO",BD!$C149,"") | Q149: =IF(N149 = "VENCIDO",BD!$E149,"") | R149: =IF(N149 = "VENCIDO",BD!$F149,"") | S149: =IF(N149 = "VENCIDO",BD!$G149,"") | T149: =IF(AND(TODAY()>BD!$C149, OR(BD!$D149="PENDENTE", BD!$D149="")), TODAY()-BD!$C149, "")
B150: ='MAR-26'!A3 -> 0 | C150: ='MAR-26'!B3 -> 0 | D150: ='MAR-26'!C3 -> 0 | E150: ='MAR-26'!D3 -> 0 | F150: ='MAR-26'!E3 -> 0 | G150: ='MAR-26'!F3 -> 0 | H150: =IF(OR(D150 = "",D150="PENDENTE"), 0, IF(OR(D150<=C150,M150=1),G150,(G150*0.1966/100)*(D150-C150)+G150)) -> 0 | I150: MAR | J150: =IF(OR(D150="PENDENTE", D150=0, D150=""), "", UPPER(TEXT(D150, "mmm"))) | K150: =IF(OR(D150="PENDENTE", D150="", D150=0, D150=DATE(1900,1,0)), G150, 0) -> 0 | L150: =IF(K150>0, UPPER(TEXT(C150, "mmm")), "") | M150: ='MAR-26'!H3 -> 0 | N150: =IF(BD!$C150="","",IF(AND(TODAY()>BD!$C150,OR(BD!$D150="PENDENTE",BD!$D150="")),"VENCIDO","")) | O150: =IF(N150 = "VENCIDO",BD!$B150,"") | P150: =IF(N150 = "VENCIDO",BD!$C150,"") | Q150: =IF(N150 = "VENCIDO",BD!$E150,"") | R150: =IF(N150 = "VENCIDO",BD!$F150,"") | S150: =IF(N150 = "VENCIDO",BD!$G150,"") | T150: =IF(AND(TODAY()>BD!$C150, OR(BD!$D150="PENDENTE", BD!$D150="")), TODAY()-BD!$C150, "")
B151: ='MAR-26'!A4 -> 0 | C151: ='MAR-26'!B4 -> 0 | D151: ='MAR-26'!C4 -> 0 | E151: ='MAR-26'!D4 -> 0 | F151: ='MAR-26'!E4 -> 0 | G151: ='MAR-26'!F4 -> 0 | H151: =IF(OR(D151 = "",D151="PENDENTE"), 0, IF(OR(D151<=C151,M151=1),G151,(G151*0.1966/100)*(D151-C151)+G151)) -> 0 | I151: MAR | J151: =IF(OR(D151="PENDENTE", D151=0, D151=""), "", UPPER(TEXT(D151, "mmm"))) | K151: =IF(OR(D151="PENDENTE", D151="", D151=0, D151=DATE(1900,1,0)), G151, 0) -> 0 | L151: =IF(K151>0, UPPER(TEXT(C151, "mmm")), "") | M151: ='MAR-26'!H4 -> 0 | N151: =IF(BD!$C151="","",IF(AND(TODAY()>BD!$C151,OR(BD!$D151="PENDENTE",BD!$D151="")),"VENCIDO","")) | O151: =IF(N151 = "VENCIDO",BD!$B151,"") | P151: =IF(N151 = "VENCIDO",BD!$C151,"") | Q151: =IF(N151 = "VENCIDO",BD!$E151,"") | R151: =IF(N151 = "VENCIDO",BD!$F151,"") | S151: =IF(N151 = "VENCIDO",BD!$G151,"") | T151: =IF(AND(TODAY()>BD!$C151, OR(BD!$D151="PENDENTE", BD!$D151="")), TODAY()-BD!$C151, "")
B152: ='MAR-26'!A5 -> 0 | C152: ='MAR-26'!B5 -> 0 | D152: ='MAR-26'!C5 -> 0 | E152: ='MAR-26'!D5 -> 0 | F152: ='MAR-26'!E5 -> 0 | G152: ='MAR-26'!F5 -> 0 | H152: =IF(OR(D152 = "",D152="PENDENTE"), 0, IF(OR(D152<=C152,M152=1),G152,(G152*0.1966/100)*(D152-C152)+G152)) -> 0 | I152: MAR | J152: =IF(OR(D152="PENDENTE", D152=0, D152=""), "", UPPER(TEXT(D152, "mmm"))) | K152: =IF(OR(D152="PENDENTE", D152="", D152=0, D152=DATE(1900,1,0)), G152, 0) -> 0 | L152: =IF(K152>0, UPPER(TEXT(C152, "mmm")), "") | M152: ='MAR-26'!H5 -> 0 | N152: =IF(BD!$C152="","",IF(AND(TODAY()>BD!$C152,OR(BD!$D152="PENDENTE",BD!$D152="")),"VENCIDO","")) | O152: =IF(N152 = "VENCIDO",BD!$B152,"") | P152: =IF(N152 = "VENCIDO",BD!$C152,"") | Q152: =IF(N152 = "VENCIDO",BD!$E152,"") | R152: =IF(N152 = "VENCIDO",BD!$F152,"") | S152: =IF(N152 = "VENCIDO",BD!$G152,"") | T152: =IF(AND(TODAY()>BD!$C152, OR(BD!$D152="PENDENTE", BD!$D152="")), TODAY()-BD!$C152, "")
B153: ='MAR-26'!A6 -> 0 | C153: ='MAR-26'!B6 -> 0 | D153: ='MAR-26'!C6 -> 0 | E153: ='MAR-26'!D6 -> 0 | F153: ='MAR-26'!E6 -> 0 | G153: ='MAR-26'!F6 -> 0 | H153: =IF(OR(D153 = "",D153="PENDENTE"), 0, IF(OR(D153<=C153,M153=1),G153,(G153*0.1966/100)*(D153-C153)+G153)) -> 0 | I153: MAR | J153: =IF(OR(D153="PENDENTE", D153=0, D153=""), "", UPPER(TEXT(D153, "mmm"))) | K153: =IF(OR(D153="PENDENTE", D153="", D153=0, D153=DATE(1900,1,0)), G153, 0) -> 0 | L153: =IF(K153>0, UPPER(TEXT(C153, "mmm")), "") | M153: ='MAR-26'!H6 -> 0 | N153: =IF(BD!$C153="","",IF(AND(TODAY()>BD!$C153,OR(BD!$D153="PENDENTE",BD!$D153="")),"VENCIDO","")) | O153: =IF(N153 = "VENCIDO",BD!$B153,"") | P153: =IF(N153 = "VENCIDO",BD!$C153,"") | Q153: =IF(N153 = "VENCIDO",BD!$E153,"") | R153: =IF(N153 = "VENCIDO",BD!$F153,"") | S153: =IF(N153 = "VENCIDO",BD!$G153,"") | T153: =IF(AND(TODAY()>BD!$C153, OR(BD!$D153="PENDENTE", BD!$D153="")), TODAY()-BD!$C153, "")
B154: ='MAR-26'!A7 -> 0 | C154: ='MAR-26'!B7 -> 0 | D154: ='MAR-26'!C7 -> 0 | E154: ='MAR-26'!D7 -> 0 | F154: ='MAR-26'!E7 -> 0 | G154: ='MAR-26'!F7 -> 0 | H154: =IF(OR(D154 = "",D154="PENDENTE"), 0, IF(OR(D154<=C154,M154=1),G154,(G154*0.1966/100)*(D154-C154)+G154)) -> 0 | I154: MAR | J154: =IF(OR(D154="PENDENTE", D154=0, D154=""), "", UPPER(TEXT(D154, "mmm"))) | K154: =IF(OR(D154="PENDENTE", D154="", D154=0, D154=DATE(1900,1,0)), G154, 0) -> 0 | L154: =IF(K154>0, UPPER(TEXT(C154, "mmm")), "") | M154: ='MAR-26'!H7 -> 0 | N154: =IF(BD!$C154="","",IF(AND(TODAY()>BD!$C154,OR(BD!$D154="PENDENTE",BD!$D154="")),"VENCIDO","")) | O154: =IF(N154 = "VENCIDO",BD!$B154,"") | P154: =IF(N154 = "VENCIDO",BD!$C154,"") | Q154: =IF(N154 = "VENCIDO",BD!$E154,"") | R154: =IF(N154 = "VENCIDO",BD!$F154,"") | S154: =IF(N154 = "VENCIDO",BD!$G154,"") | T154: =IF(AND(TODAY()>BD!$C154, OR(BD!$D154="PENDENTE", BD!$D154="")), TODAY()-BD!$C154, "")
B155: ='MAR-26'!A8 -> 0 | C155: ='MAR-26'!B8 -> 0 | D155: ='MAR-26'!C8 -> 0 | E155: ='MAR-26'!D8 -> 0 | F155: ='MAR-26'!E8 -> 0 | G155: ='MAR-26'!F8 -> 0 | H155: =IF(OR(D155 = "",D155="PENDENTE"), 0, IF(OR(D155<=C155,M155=1),G155,(G155*0.1966/100)*(D155-C155)+G155)) -> 0 | I155: MAR | J155: =IF(OR(D155="PENDENTE", D155=0, D155=""), "", UPPER(TEXT(D155, "mmm"))) | K155: =IF(OR(D155="PENDENTE", D155="", D155=0, D155=DATE(1900,1,0)), G155, 0) -> 0 | L155: =IF(K155>0, UPPER(TEXT(C155, "mmm")), "") | M155: ='MAR-26'!H8 -> 0 | N155: =IF(BD!$C155="","",IF(AND(TODAY()>BD!$C155,OR(BD!$D155="PENDENTE",BD!$D155="")),"VENCIDO","")) | O155: =IF(N155 = "VENCIDO",BD!$B155,"") | P155: =IF(N155 = "VENCIDO",BD!$C155,"") | Q155: =IF(N155 = "VENCIDO",BD!$E155,"") | R155: =IF(N155 = "VENCIDO",BD!$F155,"") | S155: =IF(N155 = "VENCIDO",BD!$G155,"") | T155: =IF(AND(TODAY()>BD!$C155, OR(BD!$D155="PENDENTE", BD!$D155="")), TODAY()-BD!$C155, "")
B156: ='MAR-26'!A9 -> 0 | C156: ='MAR-26'!B9 -> 0 | D156: ='MAR-26'!C9 -> 0 | E156: ='MAR-26'!D9 -> 0 | F156: ='MAR-26'!E9 -> 0 | G156: ='MAR-26'!F9 -> 0 | H156: =IF(OR(D156 = "",D156="PENDENTE"), 0, IF(OR(D156<=C156,M156=1),G156,(G156*0.1966/100)*(D156-C156)+G156)) -> 0 | I156: MAR | J156: =IF(OR(D156="PENDENTE", D156=0, D156=""), "", UPPER(TEXT(D156, "mmm"))) | K156: =IF(OR(D156="PENDENTE", D156="", D156=0, D156=DATE(1900,1,0)), G156, 0) -> 0 | L156: =IF(K156>0, UPPER(TEXT(C156, "mmm")), "") | M156: ='MAR-26'!H9 -> 0 | N156: =IF(BD!$C156="","",IF(AND(TODAY()>BD!$C156,OR(BD!$D156="PENDENTE",BD!$D156="")),"VENCIDO","")) | O156: =IF(N156 = "VENCIDO",BD!$B156,"") | P156: =IF(N156 = "VENCIDO",BD!$C156,"") | Q156: =IF(N156 = "VENCIDO",BD!$E156,"") | R156: =IF(N156 = "VENCIDO",BD!$F156,"") | S156: =IF(N156 = "VENCIDO",BD!$G156,"") | T156: =IF(AND(TODAY()>BD!$C156, OR(BD!$D156="PENDENTE", BD!$D156="")), TODAY()-BD!$C156, "")
B157: ='MAR-26'!A10 -> 0 | C157: ='MAR-26'!B10 -> 0 | D157: ='MAR-26'!C10 -> 0 | E157: ='MAR-26'!D10 -> 0 | F157: ='MAR-26'!E10 -> 0 | G157: ='MAR-26'!F10 -> 0 | H157: =IF(OR(D157 = "",D157="PENDENTE"), 0, IF(OR(D157<=C157,M157=1),G157,(G157*0.1966/100)*(D157-C157)+G157)) -> 0 | I157: MAR | J157: =IF(OR(D157="PENDENTE", D157=0, D157=""), "", UPPER(TEXT(D157, "mmm"))) | K157: =IF(OR(D157="PENDENTE", D157="", D157=0, D157=DATE(1900,1,0)), G157, 0) -> 0 | L157: =IF(K157>0, UPPER(TEXT(C157, "mmm")), "") | M157: ='MAR-26'!H10 -> 0 | N157: =IF(BD!$C157="","",IF(AND(TODAY()>BD!$C157,OR(BD!$D157="PENDENTE",BD!$D157="")),"VENCIDO","")) | O157: =IF(N157 = "VENCIDO",BD!$B157,"") | P157: =IF(N157 = "VENCIDO",BD!$C157,"") | Q157: =IF(N157 = "VENCIDO",BD!$E157,"") | R157: =IF(N157 = "VENCIDO",BD!$F157,"") | S157: =IF(N157 = "VENCIDO",BD!$G157,"") | T157: =IF(AND(TODAY()>BD!$C157, OR(BD!$D157="PENDENTE", BD!$D157="")), TODAY()-BD!$C157, "")
B158: ='MAR-26'!A11 -> 0 | C158: ='MAR-26'!B11 -> 0 | D158: ='MAR-26'!C11 -> 0 | E158: ='MAR-26'!D11 -> 0 | F158: ='MAR-26'!E11 -> 0 | G158: ='MAR-26'!F11 -> 0 | H158: =IF(OR(D158 = "",D158="PENDENTE"), 0, IF(OR(D158<=C158,M158=1),G158,(G158*0.1966/100)*(D158-C158)+G158)) -> 0 | I158: MAR | J158: =IF(OR(D158="PENDENTE", D158=0, D158=""), "", UPPER(TEXT(D158, "mmm"))) | K158: =IF(OR(D158="PENDENTE", D158="", D158=0, D158=DATE(1900,1,0)), G158, 0) -> 0 | L158: =IF(K158>0, UPPER(TEXT(C158, "mmm")), "") | M158: ='MAR-26'!H11 -> 0 | N158: =IF(BD!$C158="","",IF(AND(TODAY()>BD!$C158,OR(BD!$D158="PENDENTE",BD!$D158="")),"VENCIDO","")) | O158: =IF(N158 = "VENCIDO",BD!$B158,"") | P158: =IF(N158 = "VENCIDO",BD!$C158,"") | Q158: =IF(N158 = "VENCIDO",BD!$E158,"") | R158: =IF(N158 = "VENCIDO",BD!$F158,"") | S158: =IF(N158 = "VENCIDO",BD!$G158,"") | T158: =IF(AND(TODAY()>BD!$C158, OR(BD!$D158="PENDENTE", BD!$D158="")), TODAY()-BD!$C158, "")
B159: ='MAR-26'!A12 -> 0 | C159: ='MAR-26'!B12 -> 0 | D159: ='MAR-26'!C12 -> 0 | E159: ='MAR-26'!D12 -> 0 | F159: ='MAR-26'!E12 -> 0 | G159: ='MAR-26'!F12 -> 0 | H159: =IF(OR(D159 = "",D159="PENDENTE"), 0, IF(OR(D159<=C159,M159=1),G159,(G159*0.1966/100)*(D159-C159)+G159)) -> 0 | I159: MAR | J159: =IF(OR(D159="PENDENTE", D159=0, D159=""), "", UPPER(TEXT(D159, "mmm"))) | K159: =IF(OR(D159="PENDENTE", D159="", D159=0, D159=DATE(1900,1,0)), G159, 0) -> 0 | L159: =IF(K159>0, UPPER(TEXT(C159, "mmm")), "") | M159: ='MAR-26'!H12 -> 0 | N159: =IF(BD!$C159="","",IF(AND(TODAY()>BD!$C159,OR(BD!$D159="PENDENTE",BD!$D159="")),"VENCIDO","")) | O159: =IF(N159 = "VENCIDO",BD!$B159,"") | P159: =IF(N159 = "VENCIDO",BD!$C159,"") | Q159: =IF(N159 = "VENCIDO",BD!$E159,"") | R159: =IF(N159 = "VENCIDO",BD!$F159,"") | S159: =IF(N159 = "VENCIDO",BD!$G159,"") | T159: =IF(AND(TODAY()>BD!$C159, OR(BD!$D159="PENDENTE", BD!$D159="")), TODAY()-BD!$C159, "")
B160: ='MAR-26'!A13 -> 0 | C160: ='MAR-26'!B13 -> 0 | D160: ='MAR-26'!C13 -> 0 | E160: ='MAR-26'!D13 -> 0 | F160: ='MAR-26'!E13 -> 0 | G160: ='MAR-26'!F13 -> 0 | H160: =IF(OR(D160 = "",D160="PENDENTE"), 0, IF(OR(D160<=C160,M160=1),G160,(G160*0.1966/100)*(D160-C160)+G160)) -> 0 | I160: MAR | J160: =IF(OR(D160="PENDENTE", D160=0, D160=""), "", UPPER(TEXT(D160, "mmm"))) | K160: =IF(OR(D160="PENDENTE", D160="", D160=0, D160=DATE(1900,1,0)), G160, 0) -> 0 | L160: =IF(K160>0, UPPER(TEXT(C160, "mmm")), "") | M160: ='MAR-26'!H13 -> 0 | N160: =IF(BD!$C160="","",IF(AND(TODAY()>BD!$C160,OR(BD!$D160="PENDENTE",BD!$D160="")),"VENCIDO","")) | O160: =IF(N160 = "VENCIDO",BD!$B160,"") | P160: =IF(N160 = "VENCIDO",BD!$C160,"") | Q160: =IF(N160 = "VENCIDO",BD!$E160,"") | R160: =IF(N160 = "VENCIDO",BD!$F160,"") | S160: =IF(N160 = "VENCIDO",BD!$G160,"") | T160: =IF(AND(TODAY()>BD!$C160, OR(BD!$D160="PENDENTE", BD!$D160="")), TODAY()-BD!$C160, "")
B161: ='MAR-26'!A14 -> 0 | C161: ='MAR-26'!B14 -> 0 | D161: ='MAR-26'!C14 -> 0 | E161: ='MAR-26'!D14 -> 0 | F161: ='MAR-26'!E14 -> 0 | G161: ='MAR-26'!F14 -> 0 | H161: =IF(OR(D161 = "",D161="PENDENTE"), 0, IF(OR(D161<=C161,M161=1),G161,(G161*0.1966/100)*(D161-C161)+G161)) -> 0 | I161: MAR | J161: =IF(OR(D161="PENDENTE", D161=0, D161=""), "", UPPER(TEXT(D161, "mmm"))) | K161: =IF(OR(D161="PENDENTE", D161="", D161=0, D161=DATE(1900,1,0)), G161, 0) -> 0 | L161: =IF(K161>0, UPPER(TEXT(C161, "mmm")), "") | M161: ='MAR-26'!H14 -> 0 | N161: =IF(BD!$C161="","",IF(AND(TODAY()>BD!$C161,OR(BD!$D161="PENDENTE",BD!$D161="")),"VENCIDO","")) | O161: =IF(N161 = "VENCIDO",BD!$B161,"") | P161: =IF(N161 = "VENCIDO",BD!$C161,"") | Q161: =IF(N161 = "VENCIDO",BD!$E161,"") | R161: =IF(N161 = "VENCIDO",BD!$F161,"") | S161: =IF(N161 = "VENCIDO",BD!$G161,"") | T161: =IF(AND(TODAY()>BD!$C161, OR(BD!$D161="PENDENTE", BD!$D161="")), TODAY()-BD!$C161, "")
